<?xml version="1.0"?>

<robot name="Mecanum-Left" xmlns:xacro="http://www.ros.org/wiki/xacro" >
  <link
    name="base_link">
    <inertial>
      <origin
        xyz="-5.71071320654166E-07 1.24074703998625E-17 -8.40087960733809E-19"
        rpy="0 0 0" />
      <mass
        value="0.0110925597603563" />
      <inertia
        ixx="1.39920510272198E-06"
        ixy="6.03598608368132E-22"
        ixz="2.70201401925188E-21"
        iyy="9.49230299056441E-07"
        iyz="-8.48228743085689E-23"
        izz="9.49230299056441E-07" />
    </inertial>
    <visual>
      <origin
        xyz="0 0 0"
        rpy="0 0 0" />
      <geometry>
        <mesh
          filename="file://$(find icarus_pi)/Mesh/Mecanum-Left/meshes/base_link.STL" />
      </geometry>
      <material
        name="">
        <color
          rgba="0.792156862745098 0.819607843137255 0.933333333333333 1" />
      </material>
    </visual>
    <collision>
      <origin
        xyz="0 0 0"
        rpy="0 0 0" />
      <geometry>
        <mesh
          filename="file://$(find icarus_pi)/Mesh/Mecanum-Left/meshes/base_link.STL" />
      </geometry>
    </collision>
  </link>
  <link
    name="Mecanum_roller_link_1">
    <inertial>
      <origin
        xyz="4.19537259525784E-05 -9.19403442267708E-17 -4.5102810375397E-17"
        rpy="0 0 0" />
      <mass
        value="0.00104310145784987" />
      <inertia
        ixx="9.96758957260103E-09"
        ixy="8.47860127866853E-24"
        ixz="-4.54949336904165E-24"
        iyy="3.79225492604175E-08"
        iyz="3.30872245021211E-24"
        izz="3.79225492604176E-08" />
    </inertial>
    <visual>
      <origin
        xyz="0 0 0"
        rpy="0 0 0" />
      <geometry>
        <mesh
          filename="file://$(find icarus_pi)/Mesh/Mecanum-Left/meshes/Mecanum_roller_link_1.STL" />
      </geometry>
      <material
        name="">
        <color
          rgba="0.792156862745098 0.819607843137255 0.933333333333333 1" />
      </material>
    </visual>
    <collision>
      <origin
        xyz="0 0 0"
        rpy="0 0 0" />
      <geometry>
        <mesh
          filename="file://$(find icarus_pi)/Mesh/Mecanum-Left/meshes/Mecanum_roller_link_1.STL" />
      </geometry>
    </collision>
  </link>
  <joint
    name="Mecanum_roller_joint_1"
    type="continuous">
    <origin
      xyz="0.00012912 0.014344 0.0095825"
      rpy="-2.7656 0.6249 2.6298" />
    <parent
      link="base_link" />
    <child
      link="Mecanum_roller_link_1" />
    <axis
      xyz="1 0 0" />
  </joint>
  <link
    name="Mecanum_roller_link_2">
    <inertial>
      <origin
        xyz="-4.19537259514885E-05 -2.77555756156289E-17 -9.71445146547012E-17"
        rpy="0 0 0" />
      <mass
        value="0.00104310145784987" />
      <inertia
        ixx="9.96758957260103E-09"
        ixy="1.68021061924834E-24"
        ixz="-5.37667398159468E-24"
        iyy="3.79225492604175E-08"
        iyz="-1.03397576569128E-25"
        izz="3.79225492604175E-08" />
    </inertial>
    <visual>
      <origin
        xyz="0 0 0"
        rpy="0 0 0" />
      <geometry>
        <mesh
          filename="file://$(find icarus_pi)/Mesh/Mecanum-Left/meshes/Mecanum_roller_link_2.STL" />
      </geometry>
      <material
        name="">
        <color
          rgba="0.792156862745098 0.819607843137255 0.933333333333333 1" />
      </material>
    </visual>
    <collision>
      <origin
        xyz="0 0 0"
        rpy="0 0 0" />
      <geometry>
        <mesh
          filename="file://$(find icarus_pi)/Mesh/Mecanum-Left/meshes/Mecanum_roller_link_2.STL" />
      </geometry>
    </collision>
  </link>
  <joint
    name="Mecanum_roller_joint_2"
    type="continuous">
    <origin
      xyz="-0.00012933 0.0045802 0.016631"
      rpy="1.6775 -0.19406 -0.76608" />
    <parent
      link="base_link" />
    <child
      link="Mecanum_roller_link_2" />
    <axis
      xyz="1 0 0" />
  </joint>
  <link
    name="Mecanum_roller_link_3">
    <inertial>
      <origin
        xyz="-4.19537259517232E-05 6.24500451351651E-17 -1.45716771982052E-16"
        rpy="0 0 0" />
      <mass
        value="0.00104310145784987" />
      <inertia
        ixx="9.96758957260103E-09"
        ixy="4.39439700418796E-24"
        ixz="-8.27180612553028E-25"
        iyy="3.79225492604175E-08"
        iyz="-1.65436122510606E-24"
        izz="3.79225492604175E-08" />
    </inertial>
    <visual>
      <origin
        xyz="0 0 0"
        rpy="0 0 0" />
      <geometry>
        <mesh
          filename="file://$(find icarus_pi)/Mesh/Mecanum-Left/meshes/Mecanum_roller_link_3.STL" />
      </geometry>
      <material
        name="">
        <color
          rgba="0.792156862745098 0.819607843137255 0.933333333333333 1" />
      </material>
    </visual>
    <collision>
      <origin
        xyz="0 0 0"
        rpy="0 0 0" />
      <geometry>
        <mesh
          filename="file://$(find icarus_pi)/Mesh/Mecanum-Left/meshes/Mecanum_roller_link_3.STL" />
      </geometry>
    </collision>
  </link>
  <joint
    name="Mecanum_roller_joint_3"
    type="continuous">
    <origin
      xyz="0.00012912 -0.006946 0.01579"
      rpy="1.4846 0.29377 -0.73958" />
    <parent
      link="base_link" />
    <child
      link="Mecanum_roller_link_3" />
    <axis
      xyz="1 0 0" />
  </joint>
  <link
    name="Mecanum_roller_link_4">
    <inertial>
      <origin
        xyz="-4.19537259518845E-05 9.54097911787244E-17 -5.03069808033274E-17"
        rpy="0 0 0" />
      <mass
        value="0.00104310145784987" />
      <inertia
        ixx="9.9675895729459E-09"
        ixy="-5.11818004017186E-24"
        ixz="2.68833699079734E-24"
        iyy="3.79225492606102E-08"
        iyz="-8.27180612553028E-25"
        izz="3.79225492606102E-08" />
    </inertial>
    <visual>
      <origin
        xyz="0 0 0"
        rpy="0 0 0" />
      <geometry>
        <mesh
          filename="file://$(find icarus_pi)/Mesh/Mecanum-Left/meshes/Mecanum_roller_link_4.STL" />
      </geometry>
      <material
        name="">
        <color
          rgba="0.792156862745098 0.819607843137255 0.933333333333333 1" />
      </material>
    </visual>
    <collision>
      <origin
        xyz="0 0 0"
        rpy="0 0 0" />
      <geometry>
        <mesh
          filename="file://$(find icarus_pi)/Mesh/Mecanum-Left/meshes/Mecanum_roller_link_4.STL" />
      </geometry>
    </collision>
  </link>
  <joint
    name="Mecanum_roller_joint_4"
    type="continuous">
    <origin
      xyz="0.00012912 -0.015471 0.0076312"
      rpy="1.4497 0.68992 -0.41086" />
    <parent
      link="base_link" />
    <child
      link="Mecanum_roller_link_4" />
    <axis
      xyz="1 0 0" />
  </joint>
  <link
    name="Mecanum_roller_link_5">
    <inertial>
      <origin
        xyz="4.1659597956364E-05 1.04950770296597E-16 1.38777878078145E-17"
        rpy="0 0 0" />
      <mass
        value="0.00104310145784987" />
      <inertia
        ixx="9.96758957260103E-09"
        ixy="3.87740912134232E-25"
        ixz="-2.1713491079517E-24"
        iyy="3.79225492604175E-08"
        iyz="2.06795153138257E-25"
        izz="3.79225492604175E-08" />
    </inertial>
    <visual>
      <origin
        xyz="0 0 0"
        rpy="0 0 0" />
      <geometry>
        <mesh
          filename="file://$(find icarus_pi)/Mesh/Mecanum-Left/meshes/Mecanum_roller_link_5.STL" />
      </geometry>
      <material
        name="">
        <color
          rgba="0.792156862745098 0.819607843137255 0.933333333333333 1" />
      </material>
    </visual>
    <collision>
      <origin
        xyz="0 0 0"
        rpy="0 0 0" />
      <geometry>
        <mesh
          filename="file://$(find icarus_pi)/Mesh/Mecanum-Left/meshes/Mecanum_roller_link_5.STL" />
      </geometry>
    </collision>
  </link>
  <joint
    name="Mecanum_roller_joint_5"
    type="continuous">
    <origin
      xyz="0.00012912 -0.016757 -0.0040986"
      rpy="1.6948 0.7554 0.24013" />
    <parent
      link="base_link" />
    <child
      link="Mecanum_roller_link_5" />
    <axis
      xyz="1 0 0" />
  </joint>
  <link
    name="Mecanum_roller_link_6">
    <inertial>
      <origin
        xyz="-4.19537259515289E-05 6.93889390390723E-18 1.73472347597681E-18"
        rpy="0 0 0" />
      <mass
        value="0.00104310145784984" />
      <inertia
        ixx="9.96758957158561E-09"
        ixy="-6.04875822929401E-24"
        ixz="-1.15805285757424E-23"
        iyy="3.79225492599098E-08"
        iyz="8.27180612553028E-25"
        izz="3.79225492599098E-08" />
    </inertial>
    <visual>
      <origin
        xyz="0 0 0"
        rpy="0 0 0" />
      <geometry>
        <mesh
          filename="file://$(find icarus_pi)/Mesh/Mecanum-Left/meshes/Mecanum_roller_link_6.STL" />
      </geometry>
      <material
        name="">
        <color
          rgba="0.792156862745098 0.819607843137255 0.933333333333333 1" />
      </material>
    </visual>
    <collision>
      <origin
        xyz="0 0 0"
        rpy="0 0 0" />
      <geometry>
        <mesh
          filename="file://$(find icarus_pi)/Mesh/Mecanum-Left/meshes/Mecanum_roller_link_6.STL" />
      </geometry>
    </collision>
  </link>
  <joint
    name="Mecanum_roller_joint_6"
    type="continuous">
    <origin
      xyz="0.00012912 -0.010202 -0.013911"
      rpy="1.7524 0.42673 0.68129" />
    <parent
      link="base_link" />
    <child
      link="Mecanum_roller_link_6" />
    <axis
      xyz="1 0 0" />
  </joint>
  <link
    name="Mecanum_roller_link_7">
    <inertial>
      <origin
        xyz="-4.19537259513104E-05 6.24500451351651E-17 4.16333634234434E-17"
        rpy="0 0 0" />
      <mass
        value="0.00104310145784987" />
      <inertia
        ixx="9.96758957260102E-09"
        ixy="-3.30872245021211E-24"
        ixz="-1.03397576569128E-24"
        iyy="3.79225492604175E-08"
        iyz="2.48154183765908E-24"
        izz="3.79225492604175E-08" />
    </inertial>
    <visual>
      <origin
        xyz="0 0 0"
        rpy="0 0 0" />
      <geometry>
        <mesh
          filename="file://$(find icarus_pi)/Mesh/Mecanum-Left/meshes/Mecanum_roller_link_7.STL" />
      </geometry>
      <material
        name="">
        <color
          rgba="0.792156862745098 0.819607843137255 0.933333333333333 1" />
      </material>
    </visual>
    <collision>
      <origin
        xyz="0 0 0"
        rpy="0 0 0" />
      <geometry>
        <mesh
          filename="file://$(find icarus_pi)/Mesh/Mecanum-Left/meshes/Mecanum_roller_link_7.STL" />
      </geometry>
    </collision>
  </link>
  <joint
    name="Mecanum_roller_joint_7"
    type="continuous">
    <origin
      xyz="0.00012912 0.0011266 -0.017214"
      rpy="2.5112 -0.051481 0.78407" />
    <parent
      link="base_link" />
    <child
      link="Mecanum_roller_link_7" />
    <axis
      xyz="1 0 0" />
  </joint>
  <link
    name="Mecanum_roller_link_8">
    <inertial>
      <origin
        xyz="4.16595979570254E-05 -8.67361737988404E-18 -6.93889390390723E-18"
        rpy="0 0 0" />
      <mass
        value="0.00104310145784987" />
      <inertia
        ixx="9.96758957226301E-09"
        ixy="-4.23930063933427E-24"
        ixz="-3.30872245021211E-24"
        iyy="3.79225492602485E-08"
        iyz="-4.13590306276514E-25"
        izz="3.79225492602485E-08" />
    </inertial>
    <visual>
      <origin
        xyz="0 0 0"
        rpy="0 0 0" />
      <geometry>
        <mesh
          filename="file://$(find icarus_pi)/Mesh/Mecanum-Left/meshes/Mecanum_roller_link_8.STL" />
      </geometry>
      <material
        name="">
        <color
          rgba="0.792156862745098 0.819607843137255 0.933333333333333 1" />
      </material>
    </visual>
    <collision>
      <origin
        xyz="0 0 0"
        rpy="0 0 0" />
      <geometry>
        <mesh
          filename="file://$(find icarus_pi)/Mesh/Mecanum-Left/meshes/Mecanum_roller_link_8.STL" />
      </geometry>
    </collision>
  </link>
  <joint
    name="Mecanum_roller_joint_8"
    type="continuous">
    <origin
      xyz="-0.00012933 0.012113 -0.012282"
      rpy="-1.7252 -0.51523 0.6222" />
    <parent
      link="base_link" />
    <child
      link="Mecanum_roller_link_8" />
    <axis
      xyz="1 0 0" />
  </joint>
  <link
    name="Mecanum_roller_link_9">
    <inertial>
      <origin
        xyz="-4.19537259509657E-05 8.02309607639273E-17 -1.04083408558608E-17"
        rpy="0 0 0" />
      <mass
        value="0.00104310145784987" />
      <inertia
        ixx="9.96758957260103E-09"
        ixy="-3.36042123849667E-25"
        ixz="2.99852972050473E-24"
        iyy="3.79225492604175E-08"
        iyz="-4.13590306276514E-25"
        izz="3.79225492604175E-08" />
    </inertial>
    <visual>
      <origin
        xyz="0 0 0"
        rpy="0 0 0" />
      <geometry>
        <mesh
          filename="file://$(find icarus_pi)/Mesh/Mecanum-Left/meshes/Mecanum_roller_link_9.STL" />
      </geometry>
      <material
        name="">
        <color
          rgba="0.792156862745098 0.819607843137255 0.933333333333333 1" />
      </material>
    </visual>
    <collision>
      <origin
        xyz="0 0 0"
        rpy="0 0 0" />
      <geometry>
        <mesh
          filename="file://$(find icarus_pi)/Mesh/Mecanum-Left/meshes/Mecanum_roller_link_9.STL" />
      </geometry>
    </collision>
  </link>
  <joint
    name="Mecanum_roller_joint_9"
    type="continuous">
    <origin
      xyz="0.00012912 0.017148 -0.0018797"
      rpy="1.5575 -0.78024 0.10117" />
    <parent
      link="base_link" />
    <child
      link="Mecanum_roller_link_9" />
    <axis
      xyz="1 0 0" />
  </joint>

    <ros2_control name="gazeboSimSystem" type="system">	
		<hardware>
			<plugin>gazebo_ros2_control/GazeboSystem</plugin>
		</hardware>

		<joint name="Mecanum_roller_joint_1">
			<command_interface name="velocity">
				<param name="min">-100</param>
				<param name="max">100</param>
			</command_interface>
			<state_interface name="position"/>
			<state_interface name="velocity"/>
		</joint>

		<joint name="Mecanum_roller_joint_2">
			<command_interface name="velocity">
				<param name="min">-100</param>
				<param name="max">100</param>
			</command_interface>
			<state_interface name="position"/>
			<state_interface name="velocity"/>
		</joint>

    		<joint name="Mecanum_roller_joint_3">
			<command_interface name="velocity">
				<param name="min">-100</param>
				<param name="max">100</param>
			</command_interface>
			<state_interface name="position"/>
			<state_interface name="velocity"/>
		</joint>

    		<joint name="Mecanum_roller_joint_4">
			<command_interface name="velocity">
				<param name="min">-100</param>
				<param name="max">100</param>
			</command_interface>
			<state_interface name="position"/>
			<state_interface name="velocity"/>
		</joint>

    		<joint name="Mecanum_roller_joint_5">
			<command_interface name="velocity">
				<param name="min">-100</param>
				<param name="max">100</param>
			</command_interface>
			<state_interface name="position"/>
			<state_interface name="velocity"/>
		</joint>

    		<joint name="Mecanum_roller_joint_6">
			<command_interface name="velocity">
				<param name="min">-100</param>
				<param name="max">100</param>
			</command_interface>
			<state_interface name="position"/>
			<state_interface name="velocity"/>
		</joint>

    		<joint name="Mecanum_roller_joint_7">
			<command_interface name="velocity">
				<param name="min">-100</param>
				<param name="max">100</param>
			</command_interface>
			<state_interface name="position"/>
			<state_interface name="velocity"/>
		</joint>

    		<joint name="Mecanum_roller_joint_8">
			<command_interface name="velocity">
				<param name="min">-100</param>
				<param name="max">100</param>
			</command_interface>
			<state_interface name="position"/>
			<state_interface name="velocity"/>
		</joint>

    		<joint name="Mecanum_roller_joint_9">
			<command_interface name="velocity">
				<param name="min">-100</param>
				<param name="max">100</param>
			</command_interface>
			<state_interface name="position"/>
			<state_interface name="velocity"/>
		</joint>
	</ros2_control>

  	<gazebo>
		<plugin filename="libgazebo_ros2_control.so" name="gazebo_ros2_control">
			<parameters>$(find icarus_pi)/config/controllers.yaml</parameters>
			<robot_param>robot_description</robot_param>
			<robot_param_node>robot_state_publisher</robot_param_node>
			<controller_manager_name>icarus_controller_manager</controller_manager_name>
		</plugin>
	</gazebo>


</robot>