<?xml version="1.0" encoding="utf-8"?>
<!-- This URDF was automatically created by SolidWorks to URDF Exporter! Originally created by Stephen Brawner (brawner@gmail.com) 
     Commit Version: 1.6.0-4-g7f85cfe  Build Version: 1.6.7995.38578
     For more information, please see http://wiki.ros.org/sw_urdf_exporter -->
<robot
  name="Mecanum-Left">
  <link
    name="base_link">
    <inertial>
      <origin
        xyz="0.00465786271618245 4.16333634234434E-17 -1.38777878078145E-17"
        rpy="0 0 0" />
      <mass
        value="0.0110925597603562" />
      <inertia
        ixx="1.39920510272198E-06"
        ixy="1.27054942088145E-21"
        ixz="4.2351647362715E-22"
        iyy="9.49230299056441E-07"
        iyz="-1.58818677610181E-22"
        izz="9.4923029905644E-07" />
    </inertial>
    <visual>
      <origin
        xyz="0 0 0"
        rpy="0 0 0" />
      <geometry>
        <mesh
          filename="package://Mecanum-Left/meshes/base_link.STL" />
      </geometry>
      <material
        name="">
        <color
          rgba="0.792156862745098 0.819607843137255 0.933333333333333 1" />
      </material>
    </visual>
    <collision>
      <origin
        xyz="0 0 0"
        rpy="0 0 0" />
      <geometry>
        <mesh
          filename="package://Mecanum-Left/meshes/base_link.STL" />
      </geometry>
    </collision>
  </link>
  <link
    name="Mecanum_Roller_Link_1">
    <inertial>
      <origin
        xyz="0.00465012992570832 0.0159564485202234 -0.00655587244398443"
        rpy="0 0 0" />
      <mass
        value="0.00104310145784987" />
      <inertia
        ixx="2.39450694160864E-08"
        ixy="-5.43070314612507E-09"
        ixz="-1.28793402831617E-08"
        iyy="3.58125453831571E-08"
        iyz="-5.00404039756562E-09"
        izz="2.60550732930648E-08" />
    </inertial>
    <visual>
      <origin
        xyz="0 0 0"
        rpy="0 0 0" />
      <geometry>
        <mesh
          filename="package://Mecanum-Left/meshes/Mecanum_Roller_Link_1.STL" />
      </geometry>
      <material
        name="">
        <color
          rgba="0.792156862745098 0.819607843137255 0.933333333333333 1" />
      </material>
    </visual>
    <collision>
      <origin
        xyz="0 0 0"
        rpy="0 0 0" />
      <geometry>
        <mesh
          filename="package://Mecanum-Left/meshes/Mecanum_Roller_Link_1.STL" />
      </geometry>
    </collision>
  </link>
  <joint
    name="Mecanum_Roller_1"
    type="continuous">
    <origin
      xyz="0 0 0"
      rpy="0 0 0" />
    <parent
      link="base_link" />
    <child
      link="Mecanum_Roller_Link_1" />
    <axis
      xyz="-1 0 0" />
  </joint>
  <link
    name="Mecanum_Roller_Link_2">
    <inertial>
      <origin
        xyz="0.00465012992570854 0.0164373822985098 0.00523451774788974"
        rpy="0 0 0" />
      <mass
        value="0.00104310145784987" />
      <inertia
        ixx="2.39450694165093E-08"
        ixy="4.11852038759365E-09"
        ixz="-1.33569357490345E-08"
        iyy="3.67090107418543E-08"
        iyz="3.93567458601291E-09"
        izz="2.51586079350725E-08" />
    </inertial>
    <visual>
      <origin
        xyz="0 0 0"
        rpy="0 0 0" />
      <geometry>
        <mesh
          filename="package://Mecanum-Left/meshes/Mecanum_Roller_Link_2.STL" />
      </geometry>
      <material
        name="">
        <color
          rgba="0.792156862745098 0.819607843137255 0.933333333333333 1" />
      </material>
    </visual>
    <collision>
      <origin
        xyz="0 0 0"
        rpy="0 0 0" />
      <geometry>
        <mesh
          filename="package://Mecanum-Left/meshes/Mecanum_Roller_Link_2.STL" />
      </geometry>
    </collision>
  </link>
  <joint
    name="Mecanum_Roller_2"
    type="continuous">
    <origin
      xyz="0 0 0"
      rpy="0 0 0" />
    <parent
      link="base_link" />
    <child
      link="Mecanum_Roller_Link_2" />
    <axis
      xyz="-1 0 0" />
  </joint>
  <link
    name="Mecanum_Roller_Link_3">
    <inertial>
      <origin
        xyz="0.0046501299257088 0.00922708221816762 0.0145756189103416"
        rpy="0 0 0" />
      <mass
        value="0.00104310145784987" />
      <inertia
        ixx="2.3945069416081E-08"
        ixy="1.17406424597669E-08"
        ixz="-7.58467253233599E-09"
        iyy="2.80607796917968E-08"
        iyz="6.37088583708256E-09"
        izz="3.38068389844161E-08" />
    </inertial>
    <visual>
      <origin
        xyz="0 0 0"
        rpy="0 0 0" />
      <geometry>
        <mesh
          filename="package://Mecanum-Left/meshes/Mecanum_Roller_Link_3.STL" />
      </geometry>
      <material
        name="">
        <color
          rgba="0.792156862745098 0.819607843137255 0.933333333333333 1" />
      </material>
    </visual>
    <collision>
      <origin
        xyz="0 0 0"
        rpy="0 0 0" />
      <geometry>
        <mesh
          filename="package://Mecanum-Left/meshes/Mecanum_Roller_Link_3.STL" />
      </geometry>
    </collision>
  </link>
  <joint
    name="Mecanum_Roller_3"
    type="continuous">
    <origin
      xyz="0 0 0"
      rpy="0 0 0" />
    <parent
      link="base_link" />
    <child
      link="Mecanum_Roller_Link_3" />
    <axis
      xyz="-1 0 0" />
  </joint>
  <link
    name="Mecanum_Roller_Link_4">
    <inertial>
      <origin
        xyz="0.00465012992570908 -0.0023006721796512 0.0170966259946842"
        rpy="0 0 0" />
      <mass
        value="0.00104310145784987" />
      <inertia
        ixx="2.39450694162611E-08"
        ixy="1.3869187442207E-08"
        ixz="1.73654325661722E-09"
        iyy="2.41608152099063E-08"
        iyz="-1.72308915457882E-09"
        izz="3.77068034666068E-08" />
    </inertial>
    <visual>
      <origin
        xyz="0 0 0"
        rpy="0 0 0" />
      <geometry>
        <mesh
          filename="package://Mecanum-Left/meshes/Mecanum_Roller_Link_4.STL" />
      </geometry>
      <material
        name="">
        <color
          rgba="0.792156862745098 0.819607843137255 0.933333333333333 1" />
      </material>
    </visual>
    <collision>
      <origin
        xyz="0 0 0"
        rpy="0 0 0" />
      <geometry>
        <mesh
          filename="package://Mecanum-Left/meshes/Mecanum_Roller_Link_4.STL" />
      </geometry>
    </collision>
  </link>
  <joint
    name="Mecanum_Roller_4"
    type="continuous">
    <origin
      xyz="0 0 0"
      rpy="0 0 0" />
    <parent
      link="base_link" />
    <child
      link="Mecanum_Roller_Link_4" />
    <axis
      xyz="-1 0 0" />
  </joint>
  <link
    name="Mecanum_Roller_Link_5">
    <inertial>
      <origin
        xyz="0.00465012992570922 -0.0127519164954881 0.011617931768281"
        rpy="0 0 0" />
      <mass
        value="0.00104310145784987" />
      <inertia
        ixx="2.39450694164201E-08"
        ixy="9.50818548160383E-09"
        ixz="1.02452111561993E-08"
        iyy="3.14546028092107E-08"
        iyz="-6.9693084203293E-09"
        izz="3.04130158675674E-08" />
    </inertial>
    <visual>
      <origin
        xyz="0 0 0"
        rpy="0 0 0" />
      <geometry>
        <mesh
          filename="package://Mecanum-Left/meshes/Mecanum_Roller_Link_5.STL" />
      </geometry>
      <material
        name="">
        <color
          rgba="0.792156862745098 0.819607843137255 0.933333333333333 1" />
      </material>
    </visual>
    <collision>
      <origin
        xyz="0 0 0"
        rpy="0 0 0" />
      <geometry>
        <mesh
          filename="package://Mecanum-Left/meshes/Mecanum_Roller_Link_5.STL" />
      </geometry>
    </collision>
  </link>
  <joint
    name="Mecanum_Roller_5"
    type="continuous">
    <origin
      xyz="0 0 0"
      rpy="0 0 0" />
    <parent
      link="base_link" />
    <child
      link="Mecanum_Roller_Link_5" />
    <axis
      xyz="-1 0 0" />
  </joint>
  <link
    name="Mecanum_Roller_Link_6">
    <inertial>
      <origin
        xyz="0.00465012992570908 -0.0172363973613206 0.000703078148570027"
        rpy="0 0 0" />
      <mass
        value="0.00104310145784987" />
      <inertia
        ixx="2.39450694162558E-08"
        ixy="6.98197862502679E-10"
        ixz="1.39600308930181E-08"
        iyy="3.7887673140902E-08"
        iyz="-6.97326259008388E-10"
        izz="2.39799455356023E-08" />
    </inertial>
    <visual>
      <origin
        xyz="0 0 0"
        rpy="0 0 0" />
      <geometry>
        <mesh
          filename="package://Mecanum-Left/meshes/Mecanum_Roller_Link_6.STL" />
      </geometry>
      <material
        name="">
        <color
          rgba="0.792156862745098 0.819607843137255 0.933333333333333 1" />
      </material>
    </visual>
    <collision>
      <origin
        xyz="0 0 0"
        rpy="0 0 0" />
      <geometry>
        <mesh
          filename="package://Mecanum-Left/meshes/Mecanum_Roller_Link_6.STL" />
      </geometry>
    </collision>
  </link>
  <joint
    name="Mecanum_Roller_6"
    type="continuous">
    <origin
      xyz="0 0 0"
      rpy="0 0 0" />
    <parent
      link="base_link" />
    <child
      link="Mecanum_Roller_Link_6" />
    <axis
      xyz="-1 0 0" />
  </joint>
  <link
    name="Mecanum_Roller_Link_7">
    <inertial>
      <origin
        xyz="0.0046501299257088 -0.0136557763405725 -0.0105407535507001"
        rpy="0 0 0" />
      <mass
        value="0.00104310145784987" />
      <inertia
        ixx="2.39450694159873E-08"
        ixy="-8.43848429615963E-09"
        ixz="1.11427970265635E-08"
        iyy="3.28280674213652E-08"
        iyz="6.72712955216745E-09"
        izz="2.90395512546916E-08" />
    </inertial>
    <visual>
      <origin
        xyz="0 0 0"
        rpy="0 0 0" />
      <geometry>
        <mesh
          filename="package://Mecanum-Left/meshes/Mecanum_Roller_Link_7.STL" />
      </geometry>
      <material
        name="">
        <color
          rgba="0.792156862745098 0.819607843137255 0.933333333333333 1" />
      </material>
    </visual>
    <collision>
      <origin
        xyz="0 0 0"
        rpy="0 0 0" />
      <geometry>
        <mesh
          filename="package://Mecanum-Left/meshes/Mecanum_Roller_Link_7.STL" />
      </geometry>
    </collision>
  </link>
  <joint
    name="Mecanum_Roller_7"
    type="continuous">
    <origin
      xyz="0 0 0"
      rpy="0 0 0" />
    <parent
      link="base_link" />
    <child
      link="Mecanum_Roller_Link_7" />
    <axis
      xyz="-1 0 0" />
  </joint>
  <link
    name="Mecanum_Roller_Link_8">
    <inertial>
      <origin
        xyz="0.00465012992570848 -0.00368546580302188 -0.016852449516171"
        rpy="0 0 0" />
      <mass
        value="0.00104310145784984" />
      <inertia
        ixx="2.39450694159121E-08"
        ixy="-1.36267058693714E-08"
        ixz="3.11172459290135E-09"
        iyy="2.46378144636646E-08"
        iyz="3.03363383434478E-09"
        izz="3.72298042122668E-08" />
    </inertial>
    <visual>
      <origin
        xyz="0 0 0"
        rpy="0 0 0" />
      <geometry>
        <mesh
          filename="package://Mecanum-Left/meshes/Mecanum_Roller_Link_8.STL" />
      </geometry>
      <material
        name="">
        <color
          rgba="0.792156862745098 0.819607843137255 0.933333333333333 1" />
      </material>
    </visual>
    <collision>
      <origin
        xyz="0 0 0"
        rpy="0 0 0" />
      <geometry>
        <mesh
          filename="package://Mecanum-Left/meshes/Mecanum_Roller_Link_8.STL" />
      </geometry>
    </collision>
  </link>
  <joint
    name="Mecanum_Roller_8"
    type="continuous">
    <origin
      xyz="0 0 0"
      rpy="0 0 0" />
    <parent
      link="base_link" />
    <child
      link="Mecanum_Roller_Link_8" />
    <axis
      xyz="-1 0 0" />
  </joint>
  <link
    name="Mecanum_Roller_Link_9">
    <inertial>
      <origin
        xyz="0.0046501299257083 0.00800931514315263 -0.0152786970589119"
        rpy="0 0 0" />
      <mass
        value="0.00104310145784987" />
      <inertia
        ixx="2.3945069416345E-08"
        ixy="-1.24388403221941E-08"
        ixz="-6.37535836070018E-09"
        iyy="2.6852975181983E-08"
        iyz="-5.67355957803555E-09"
        izz="3.50146434946699E-08" />
    </inertial>
    <visual>
      <origin
        xyz="0 0 0"
        rpy="0 0 0" />
      <geometry>
        <mesh
          filename="package://Mecanum-Left/meshes/Mecanum_Roller_Link_9.STL" />
      </geometry>
      <material
        name="">
        <color
          rgba="0.792156862745098 0.819607843137255 0.933333333333333 1" />
      </material>
    </visual>
    <collision>
      <origin
        xyz="0 0 0"
        rpy="0 0 0" />
      <geometry>
        <mesh
          filename="package://Mecanum-Left/meshes/Mecanum_Roller_Link_9.STL" />
      </geometry>
    </collision>
  </link>
  <joint
    name="Mecanum_Roller_9"
    type="continuous">
    <origin
      xyz="0 0 0"
      rpy="0 0 0" />
    <parent
      link="base_link" />
    <child
      link="Mecanum_Roller_Link_9" />
    <axis
      xyz="-1 0 0" />
  </joint>
</robot>