<?xml version="1.0" encoding="utf-8"?>
<!-- This URDF was automatically created by SolidWorks to URDF Exporter! Originally created by Stephen Brawner (brawner@gmail.com) 
     Commit Version: 1.6.0-4-g7f85cfe  Build Version: 1.6.7995.38578
     For more information, please see http://wiki.ros.org/sw_urdf_exporter -->
<robot
  name="Mecanum-8J-Right">
  <link
    name="base_link">
    <inertial>
      <origin
        xyz="1.32629873982571E-18 5.7294714265365E-18 -1.74505470488353E-18"
        rpy="0 0 0" />
      <mass
        value="0.0118270309310726" />
      <inertia
        ixx="1.05151006190876E-06"
        ixy="1.71577816127316E-21"
        ixz="4.53879010428018E-23"
        iyy="1.4398222580115E-06"
        iyz="-4.36452314976156E-22"
        izz="1.05151006190876E-06" />
    </inertial>
    <visual>
      <origin
        xyz="0 0 0"
        rpy="0 0 0" />
      <geometry>
        <mesh
          filename="package://Mecanum-8J-Right/meshes/base_link.STL" />
      </geometry>
      <material
        name="">
        <color
          rgba="0.698039215686274 0.698039215686274 0.698039215686274 1" />
      </material>
    </visual>
    <collision>
      <origin
        xyz="0 0 0"
        rpy="0 0 0" />
      <geometry>
        <mesh
          filename="package://Mecanum-8J-Right/meshes/base_link.STL" />
      </geometry>
    </collision>
  </link>
  <link
    name="Mecanum_roller_link_1">
    <inertial>
      <origin
        xyz="4.6598E-05 3.9407E-06 -4.4062E-06"
        rpy="0 0 0" />
      <mass
        value="0.0013674" />
      <inertia
        ixx="1.3974E-08"
        ixy="4.1359E-25"
        ixz="-9.4092E-24"
        iyy="4.9325E-08"
        iyz="1.2408E-24"
        izz="4.9325E-08" />
    </inertial>
    <visual>
      <origin
        xyz="0 0 0"
        rpy="0 0 0" />
      <geometry>
        <mesh
          filename="package://Mecanum-8J-Right/meshes/Mecanum_roller_link_1.STL" />
      </geometry>
      <material
        name="">
        <color
          rgba="0.69804 0.69804 0.69804 1" />
      </material>
    </visual>
    <collision>
      <origin
        xyz="0 0 0"
        rpy="0 0 0" />
      <geometry>
        <mesh
          filename="package://Mecanum-8J-Right/meshes/Mecanum_roller_link_1.STL" />
      </geometry>
    </collision>
  </link>
  <joint
    name="Mecanum_roller_joint_1"
    type="continuous">
    <origin
      xyz="0.014612 -0.0091675 0"
      rpy="-0.72969 -0.7854 -2.1306" />
    <parent
      link="base_link" />
    <child
      link="Mecanum_roller_link_1" />
    <axis
      xyz="1 0 0" />
    <dynamics
      friction="0.5" />
  </joint>
  <link
    name="Mecanum_roller_link_3">
    <inertial>
      <origin
        xyz="-5.8421E-05 4.6304E-06 3.6747E-06"
        rpy="0 0 0" />
      <mass
        value="0.0013674" />
      <inertia
        ixx="1.3974E-08"
        ixy="3.7223E-24"
        ixz="-2.2747E-24"
        iyy="4.9325E-08"
        iyz="-1.6544E-24"
        izz="4.9325E-08" />
    </inertial>
    <visual>
      <origin
        xyz="0 0 0"
        rpy="0 0 0" />
      <geometry>
        <mesh
          filename="package://Mecanum-8J-Right/meshes/Mecanum_roller_link_3.STL" />
      </geometry>
      <material
        name="">
        <color
          rgba="0.69804 0.69804 0.69804 1" />
      </material>
    </visual>
    <collision>
      <origin
        xyz="0 0 0"
        rpy="0 0 0" />
      <geometry>
        <mesh
          filename="package://Mecanum-8J-Right/meshes/Mecanum_roller_link_3.STL" />
      </geometry>
    </collision>
  </link>
  <joint
    name="Mecanum_roller_joint_3"
    type="continuous">
    <origin
      xyz="0.0091675 0.014612 0"
      rpy="-2.2416 -0.7854 -0.55983" />
    <parent
      link="base_link" />
    <child
      link="Mecanum_roller_link_3" />
    <axis
      xyz="1 0 0" />
    <dynamics
      friction="0.5" />
  </joint>
  <link
    name="Mecanum_roller_link_4">
    <inertial>
      <origin
        xyz="-5.8421E-05 9.4086E-07 5.836E-06"
        rpy="0 0 0" />
      <mass
        value="0.0013674" />
      <inertia
        ixx="1.3974E-08"
        ixy="4.1359E-25"
        ixz="-3.2669E-24"
        iyy="4.9325E-08"
        iyz="3.1019E-25"
        izz="4.9325E-08" />
    </inertial>
    <visual>
      <origin
        xyz="0 0 0"
        rpy="0 0 0" />
      <geometry>
        <mesh
          filename="package://Mecanum-8J-Right/meshes/Mecanum_roller_link_4.STL" />
      </geometry>
      <material
        name="">
        <color
          rgba="0.69804 0.69804 0.69804 1" />
      </material>
    </visual>
    <collision>
      <origin
        xyz="0 0 0"
        rpy="0 0 0" />
      <geometry>
        <mesh
          filename="package://Mecanum-8J-Right/meshes/Mecanum_roller_link_4.STL" />
      </geometry>
    </collision>
  </link>
  <joint
    name="Mecanum_roller_joint_4"
    type="continuous">
    <origin
      xyz="-0.0038664 0.016811 0"
      rpy="0.15984 0.7854 -2.916" />
    <parent
      link="base_link" />
    <child
      link="Mecanum_roller_link_4" />
    <axis
      xyz="1 0 0" />
    <dynamics
      friction="0.5" />
  </joint>
  <link
    name="Mecanum_roller_link_5">
    <inertial>
      <origin
        xyz="-5.8421E-05 4.9513E-06 3.2293E-06"
        rpy="0 0 0" />
      <mass
        value="0.0013674" />
      <inertia
        ixx="1.3974E-08"
        ixy="-5.7903E-24"
        ixz="1.5096E-23"
        iyy="4.9325E-08"
        iyz="1.2408E-24"
        izz="4.9325E-08" />
    </inertial>
    <visual>
      <origin
        xyz="0 0 0"
        rpy="0 0 0" />
      <geometry>
        <mesh
          filename="package://Mecanum-8J-Right/meshes/Mecanum_roller_link_5.STL" />
      </geometry>
      <material
        name="">
        <color
          rgba="0.69804 0.69804 0.69804 1" />
      </material>
    </visual>
    <collision>
      <origin
        xyz="0 0 0"
        rpy="0 0 0" />
      <geometry>
        <mesh
          filename="package://Mecanum-8J-Right/meshes/Mecanum_roller_link_5.STL" />
      </geometry>
    </collision>
  </link>
  <joint
    name="Mecanum_roller_joint_5"
    type="continuous">
    <origin
      xyz="-0.014621 0.0091533 0"
      rpy="0.99286 0.7854 -2.1306" />
    <parent
      link="base_link" />
    <child
      link="Mecanum_roller_link_5" />
    <axis
      xyz="1 0 0" />
    <dynamics
      friction="0.5" />
  </joint>
  <link
    name="Mecanum_roller_link_6">
    <inertial>
      <origin
        xyz="4.6598E-05 5.9111E-06 4.7784E-08"
        rpy="0 0 0" />
      <mass
        value="0.0013674" />
      <inertia
        ixx="1.3974E-08"
        ixy="3.3087E-24"
        ixz="8.2718E-25"
        iyy="4.9325E-08"
        iyz="-8.2718E-25"
        izz="4.9325E-08" />
    </inertial>
    <visual>
      <origin
        xyz="0 0 0"
        rpy="0 0 0" />
      <geometry>
        <mesh
          filename="package://Mecanum-8J-Right/meshes/Mecanum_roller_link_6.STL" />
      </geometry>
      <material
        name="">
        <color
          rgba="0.69804 0.69804 0.69804 1" />
      </material>
    </visual>
    <collision>
      <origin
        xyz="0 0 0"
        rpy="0 0 0" />
      <geometry>
        <mesh
          filename="package://Mecanum-8J-Right/meshes/Mecanum_roller_link_6.STL" />
      </geometry>
    </collision>
  </link>
  <joint
    name="Mecanum_roller_joint_6"
    type="continuous">
    <origin
      xyz="-0.016811 -0.0038664 0"
      rpy="1.5627 0.7854 -1.3452" />
    <parent
      link="base_link" />
    <child
      link="Mecanum_roller_link_6" />
    <axis
      xyz="1 0 0" />
    <dynamics
      friction="0.5" />
  </joint>
  <link
    name="Mecanum_roller_link_7">
    <inertial>
      <origin
        xyz="-0.00043342 5.7766E-06 1.2548E-06"
        rpy="0 0 0" />
      <mass
        value="0.0013674" />
      <inertia
        ixx="1.3974E-08"
        ixy="5.1117E-24"
        ixz="-1.2408E-24"
        iyy="4.9325E-08"
        iyz="-1.8612E-24"
        izz="4.9325E-08" />
    </inertial>
    <visual>
      <origin
        xyz="0 0 0"
        rpy="0 0 0" />
      <geometry>
        <mesh
          filename="package://Mecanum-8J-Right/meshes/Mecanum_roller_link_7.STL" />
      </geometry>
      <material
        name="">
        <color
          rgba="0.69804 0.69804 0.69804 1" />
      </material>
    </visual>
    <collision>
      <origin
        xyz="0 0 0"
        rpy="0 0 0" />
      <geometry>
        <mesh
          filename="package://Mecanum-8J-Right/meshes/Mecanum_roller_link_7.STL" />
      </geometry>
    </collision>
  </link>
  <joint
    name="Mecanum_roller_joint_7"
    type="continuous">
    <origin
      xyz="0.0038501 -0.016815 0"
      rpy="-1.7847 -0.7854 -2.916" />
    <parent
      link="base_link" />
    <child
      link="Mecanum_roller_link_7" />
    <axis
      xyz="1 0 0" />
    <dynamics
      friction="0.5" />
  </joint>
  <link
    name="Mecanum_roller_link_8">
    <inertial>
      <origin
        xyz="-5.8421E-05 -2.3563E-06 -5.4214E-06"
        rpy="0 0 0" />
      <mass
        value="0.0013674" />
      <inertia
        ixx="1.3974E-08"
        ixy="-1.6544E-24"
        ixz="5.0923E-24"
        iyy="4.9325E-08"
        iyz="-2.068E-25"
        izz="4.9325E-08" />
    </inertial>
    <visual>
      <origin
        xyz="0 0 0"
        rpy="0 0 0" />
      <geometry>
        <mesh
          filename="package://Mecanum-8J-Right/meshes/Mecanum_roller_link_8.STL" />
      </geometry>
      <material
        name="">
        <color
          rgba="0.69804 0.69804 0.69804 1" />
      </material>
    </visual>
    <collision>
      <origin
        xyz="0 0 0"
        rpy="0 0 0" />
      <geometry>
        <mesh
          filename="package://Mecanum-8J-Right/meshes/Mecanum_roller_link_8.STL" />
      </geometry>
    </collision>
  </link>
  <joint
    name="Mecanum_roller_joint_8"
    type="continuous">
    <origin
      xyz="-0.0091675 -0.014612 0"
      rpy="0.41001 -0.7854 2.5818" />
    <parent
      link="base_link" />
    <child
      link="Mecanum_roller_link_8" />
    <axis
      xyz="1 0 0" />
    <dynamics
      friction="0.5" />
  </joint>
  <link
    name="Mecanum_roller_link_2">
    <inertial>
      <origin
        xyz="-5.8421E-05 5.8158E-06 -1.0583E-06"
        rpy="0 0 0" />
      <mass
        value="0.0013674" />
      <inertia
        ixx="1.3974E-08"
        ixy="-8.2718E-25"
        ixz="-3.5155E-24"
        iyy="4.9325E-08"
        iyz="-4.9631E-24"
        izz="4.9325E-08" />
    </inertial>
    <visual>
      <origin
        xyz="0 0 0"
        rpy="0 0 0" />
      <geometry>
        <mesh
          filename="package://Mecanum-8J-Right/meshes/Mecanum_roller_link_2.STL" />
      </geometry>
      <material
        name="">
        <color
          rgba="0.69804 0.69804 0.69804 1" />
      </material>
    </visual>
    <collision>
      <origin
        xyz="0 0 0"
        rpy="0 0 0" />
      <geometry>
        <mesh
          filename="package://Mecanum-8J-Right/meshes/Mecanum_roller_link_2.STL" />
      </geometry>
    </collision>
  </link>
  <joint
    name="Mecanum_roller_joint_2"
    type="continuous">
    <origin
      xyz="0.016815 0.0038501 0"
      rpy="-1.3908 -0.7854 -1.3452" />
    <parent
      link="base_link" />
    <child
      link="Mecanum_roller_link_2" />
    <axis
      xyz="1 0 0" />
    <dynamics
      friction="0.5" />
  </joint>
</robot>