<?xml version="1.0" encoding="utf-8"?>
<robot xmlns:xacro="http://www.ros.org/wiki/xacro" >
  <xacro:macro name="${prefix}_Mecanum-Left" params="prefix x_reflect y_reflect r_reflect">
  <link
    name="${prefix}_link">
    <inertial>
      <origin
        xyz="8.67361737988404E-18 0 1.90819582357449E-17"
        rpy="0 0 0" />
      <mass
        value="0.0125701796053584" />
      <inertia
        ixx="1.60676184483865E-06"
        ixy="-1.1766959188554E-23"
        ixz="-2.25238700670499E-21"
        iyy="1.13583678406995E-06"
        iyz="-4.5943259120071E-23"
        izz="1.13583678406995E-06" />
    </inertial>
    <visual>
      <origin
        xyz="0 0 0"
        rpy="0 0 0" />
      <geometry>
        <mesh
            filename="file://$(find icarus_pi)/Mesh/Mecanum-Left/meshes/base_link.STL" />
      </geometry>
      <material
        name="">
        <color
          rgba="0.698039215686274 0.698039215686274 0.698039215686274 1" />
      </material>
    </visual>
    <collision>
      <origin
        xyz="0 0 0"
        rpy="0 0 0" />
      <geometry>
        <mesh
            filename="file://$(find icarus_pi)/Mesh/Mecanum-Left/meshes/base_link.STL" />
      </geometry>
    </collision>
  </link>
          <joint name="${prefix}_joint" type="continuous"> 
              <parent link="base_link"/>
              <child link="${prefix}_link"/>
              <origin xyz="${x_reflect*wheel_xoff} ${y_reflect*(chassis_width/2 + wheel_ygap)} ${-wheel_zoff}" rpy="0 0 ${r_reflect}"/>
              <axis xyz="1 0 0"/>
        </joint>
  <link
      name="${prefix}_Mecanum_roller_link_1">
    <inertial>
      <origin
        xyz="0.012194 1.7E-16 -2.4286E-16"
        rpy="0 0 0" />
      <mass
        value="0.0013674" />
      <inertia
        ixx="1.3974E-08"
        ixy="7.2378E-25"
        ixz="2.4815E-24"
        iyy="4.9325E-08"
        iyz="-2.8951E-24"
        izz="4.9325E-08" />
    </inertial>
    <visual>
      <origin
        xyz="0 0 0"
        rpy="0 0 0" />
      <geometry>
        <mesh
            filename="file://$(find icarus_pi)/Mesh/Mecanum-Left/meshes/Mecanum_roller_link_1.STL" />
      </geometry>
      <material
        name="">
        <color
          rgba="0.69804 0.69804 0.69804 1" />
      </material>
    </visual>
    <collision>
      <origin
        xyz="0 0 0"
        rpy="0 0 0" />
      <geometry>
        <mesh
            filename="file://$(find icarus_pi)/Mesh/Mecanum-Left/meshes/Mecanum_roller_link_1.STL" />
      </geometry>
    </collision>
  </link>
  <joint
    name="${prefix}_Mecanum_roller_joint_1"
    type="continuous">
    <origin
      xyz="-0.008577 0.018274 0.0061209"
      rpy="0.16992 -0.5236 -0.61548" />
    <parent
      link="base_link" />
    <child
      link="${prefix}_Mecanum_roller_link_1" />
    <axis
      xyz="1 0 0" />
  </joint>
  <link
    name="${prefix}_Mecanum_roller_link_2">
    <inertial>
      <origin
        xyz="0.0029529 -5.2042E-18 6.9389E-18"
        rpy="0 0 0" />
      <mass
        value="0.0013674" />
      <inertia
        ixx="1.3974E-08"
        ixy="-3.4638E-24"
        ixz="-7.4446E-24"
        iyy="4.9325E-08"
        iyz="0"
        izz="4.9325E-08" />
    </inertial>
    <visual>
      <origin
        xyz="0 0 0"
        rpy="0 0 0" />
      <geometry>
        <mesh
          filename="file://$(find icarus_pi)/Mesh/Mecanum-Left/meshes/Mecanum_roller_link_2.STL" />
      </geometry>
      <material
        name="">
        <color
          rgba="0.69804 0.69804 0.69804 1" />
      </material>
    </visual>
    <collision>
      <origin
        xyz="0 0 0"
        rpy="0 0 0" />
      <geometry>
        <mesh
          filename="file://$(find icarus_pi)/Mesh/Mecanum-Left/meshes/Mecanum_roller_link_2.STL" />
      </geometry>
    </collision>
  </link>
  <joint
    name="${prefix}_Mecanum_roller_joint_2"
    type="continuous">
    <origin
      xyz="0.0020425 -0.013654 0.010741"
      rpy="-2.9988 -0.5236 2.5261" />
    <parent
      link="base_link" />
    <child
      link="${prefix}_Mecanum_roller_link_2" />
    <axis
      xyz="1 0 0" />
  </joint>
  <link
    name="${prefix}_Mecanum_roller_link_3">
    <inertial>
      <origin
        xyz="-0.0023361 1.3878E-17 6.9389E-18"
        rpy="0 0 0" />
      <mass
        value="0.0013674" />
      <inertia
        ixx="1.3974E-08"
        ixy="1.7929E-22"
        ixz="-5.9557E-23"
        iyy="4.9325E-08"
        iyz="-3.3087E-24"
        izz="4.9325E-08" />
    </inertial>
    <visual>
      <origin
        xyz="0 0 0"
        rpy="0 0 0" />
      <geometry>
        <mesh
          filename="file://$(find icarus_pi)/Mesh/Mecanum-Left/meshes/Mecanum_roller_link_3.STL" />
      </geometry>
      <material
        name="">
        <color
          rgba="0.69804 0.69804 0.69804 1" />
      </material>
    </visual>
    <collision>
      <origin
        xyz="0 0 0"
        rpy="0 0 0" />
      <geometry>
        <mesh
          filename="file://$(find icarus_pi)/Mesh/Mecanum-Left/meshes/Mecanum_roller_link_3.STL" />
      </geometry>
    </collision>
  </link>
  <joint
    name="${prefix}_Mecanum_roller_joint_3"
    type="continuous">
    <origin
      xyz="0.0016064 -0.01725 -0.0016231"
      rpy="0.27441 0.7854 0" />
    <parent
      link="base_link" />
    <child
      link="${prefix}_Mecanum_roller_link_3" />
    <axis
      xyz="1 0 0" />
  </joint>
  <link
    name="${prefix}_Mecanum_roller_link_4">
    <inertial>
      <origin
        xyz="0.0030222 0 2.0817E-17"
        rpy="0 0 0" />
      <mass
        value="0.0013674" />
      <inertia
        ixx="1.3974E-08"
        ixy="-4.248E-23"
        ixz="-1.7729E-22"
        iyy="4.9325E-08"
        iyz="-8.2718E-25"
        izz="4.9325E-08" />
    </inertial>
    <visual>
      <origin
        xyz="0 0 0"
        rpy="0 0 0" />
      <geometry>
        <mesh
          filename="file://$(find icarus_pi)/Mesh/Mecanum-Left/meshes/Mecanum_roller_link_4.STL" />
      </geometry>
      <material
        name="">
        <color
          rgba="0.69804 0.69804 0.69804 1" />
      </material>
    </visual>
    <collision>
      <origin
        xyz="0 0 0"
        rpy="0 0 0" />
      <geometry>
        <mesh
          filename="file://$(find icarus_pi)/Mesh/Mecanum-Left/meshes/Mecanum_roller_link_4.STL" />
      </geometry>
    </collision>
  </link>
  <joint
    name="${prefix}_Mecanum_roller_joint_4"
    type="continuous">
    <origin
      xyz="-0.0021825 0.0021658 0.01725"
      rpy="0.21555 0 -0.7854" />
    <parent
      link="base_link" />
    <child
      link="${prefix}_Mecanum_roller_link_4" />
    <axis
      xyz="1 0 0" />
  </joint>
  <link
    name="${prefix}_Mecanum_roller_link_5">
    <inertial>
      <origin
        xyz="0.013578 2.6455E-17 -7.6328E-17"
        rpy="0 0 0" />
      <mass
        value="0.0013674" />
      <inertia
        ixx="1.3974E-08"
        ixy="-4.6896E-23"
        ixz="1.8492E-22"
        iyy="4.9325E-08"
        iyz="-2.4815E-24"
        izz="4.9325E-08" />
    </inertial>
    <visual>
      <origin
        xyz="0 0 0"
        rpy="0 0 0" />
      <geometry>
        <mesh
          filename="file://$(find icarus_pi)/Mesh/Mecanum-Left/meshes/Mecanum_roller_link_5.STL" />
      </geometry>
      <material
        name="">
        <color
          rgba="0.69804 0.69804 0.69804 1" />
      </material>
    </visual>
    <collision>
      <origin
        xyz="0 0 0"
        rpy="0 0 0" />
      <geometry>
        <mesh
          filename="file://$(find icarus_pi)/Mesh/Mecanum-Left/meshes/Mecanum_roller_link_5.STL" />
      </geometry>
    </collision>
  </link>
  <joint
    name="${prefix}_Mecanum_roller_joint_5"
    type="continuous">
    <origin
      xyz="-0.0096467 -0.00963 -0.01725"
      rpy="-0.27441 0 0.7854" />
    <parent
      link="base_link" />
    <child
      link="${prefix}_Mecanum_roller_link_5" />
    <axis
      xyz="1 0 0" />
  </joint>
  <link
    name="${prefix}_Mecanum_roller_link_6">
    <inertial>
      <origin
        xyz="0.0045113 1.2143E-17 1.7347E-18"
        rpy="0 0 0" />
      <mass
        value="0.0013674" />
      <inertia
        ixx="1.3974E-08"
        ixy="-8.8922E-24"
        ixz="0"
        iyy="4.9325E-08"
        iyz="-2.4815E-24"
        izz="4.9325E-08" />
    </inertial>
    <visual>
      <origin
        xyz="0 0 0"
        rpy="0 0 0" />
      <geometry>
        <mesh
          filename="file://$(find icarus_pi)/Mesh/Mecanum-Left/meshes/Mecanum_roller_link_6.STL" />
      </geometry>
      <material
        name="">
        <color
          rgba="0.69804 0.69804 0.69804 1" />
      </material>
    </visual>
    <collision>
      <origin
        xyz="0 0 0"
        rpy="0 0 0" />
      <geometry>
        <mesh
          filename="file://$(find icarus_pi)/Mesh/Mecanum-Left/meshes/Mecanum_roller_link_6.STL" />
      </geometry>
    </collision>
  </link>
  <joint
    name="${prefix}_Mecanum_roller_joint_6"
    type="continuous">
    <origin
      xyz="-0.0032355 -0.014474 -0.0099216"
      rpy="0.16992 0.5236 0.61548" />
    <parent
      link="base_link" />
    <child
      link="${prefix}_Mecanum_roller_link_6" />
    <axis
      xyz="1 0 0" />
  </joint>
  <link
    name="${prefix}_Mecanum_roller_link_7">
    <inertial>
      <origin
        xyz="0.018106 -3.4694E-18 1.7347E-18"
        rpy="0 0 0" />
      <mass
        value="0.0013674" />
      <inertia
        ixx="1.3974E-08"
        ixy="-1.6544E-24"
        ixz="-1.2408E-24"
        iyy="4.9325E-08"
        iyz="1.6544E-24"
        izz="4.9325E-08" />
    </inertial>
    <visual>
      <origin
        xyz="0 0 0"
        rpy="0 0 0" />
      <geometry>
        <mesh
          filename="file://$(find icarus_pi)/Mesh/Mecanum-Left/meshes/Mecanum_roller_link_7.STL" />
      </geometry>
      <material
        name="">
        <color
          rgba="0.69804 0.69804 0.69804 1" />
      </material>
    </visual>
    <collision>
      <origin
        xyz="0 0 0"
        rpy="0 0 0" />
      <geometry>
        <mesh
          filename="file://$(find icarus_pi)/Mesh/Mecanum-Left/meshes/Mecanum_roller_link_7.STL" />
      </geometry>
    </collision>
  </link>
  <joint
    name="${prefix}_Mecanum_roller_joint_7"
    type="continuous">
    <origin
      xyz="-0.012848 0.0031242 -0.021271"
      rpy="-0.35345 -0.5236 0.61548" />
    <parent
      link="base_link" />
    <child
      link="${prefix}_Mecanum_roller_joint_7" />
    <axis
      xyz="1 0 0" />
  </joint>
  <link
    name="${prefix}_Mecanum_roller_link_8">
    <inertial>
      <origin
        xyz="0.01673 -6.9389E-17 -4.8572E-17"
        rpy="0 0 0" />
      <mass
        value="0.0013674" />
      <inertia
        ixx="1.3974E-08"
        ixy="1.551E-22"
        ixz="9.9262E-23"
        iyy="4.9325E-08"
        iyz="0"
        izz="4.9325E-08" />
    </inertial>
    <visual>
      <origin
        xyz="0 0 0"
        rpy="0 0 0" />
      <geometry>
        <mesh
          filename="file://$(find icarus_pi)/Mesh/Mecanum-Left/meshes/Mecanum_roller_link_8.STL" />
      </geometry>
      <material
        name="">
        <color
          rgba="0.69804 0.69804 0.69804 1" />
      </material>
    </visual>
    <collision>
      <origin
        xyz="0 0 0"
        rpy="0 0 0" />
      <geometry>
        <mesh
          filename="file://$(find icarus_pi)/Mesh/Mecanum-Left/meshes/Mecanum_roller_link_8.STL" />
      </geometry>
    </collision>
  </link>
  <joint
    name="${prefix}_Mecanum_roller_joint_8"
    type="continuous">
    <origin
      xyz="-0.011876 0.01725 -0.011859"
      rpy="2.5615 -0.7854 0" />
    <parent
      link="base_link" />
    <child
      link="${prefix}_Mecanum_roller_link_8" />
    <axis
      xyz="1 0 0" />
  </joint>
  </xacro:macro>
</robot>