<?xml version="1.0" encoding="utf-8"?>
<robot xmlns:xacro="http://www.ros.org/wiki/xacro" >
  <xacro:macro name="MecanumR" params="prefix x_reflect y_reflect">
  <link
    name="${prefix}_link">
    <inertial>
      <origin
        xyz="-4.7771233839358E-07 2.34552518933002E-07 -2.07119508697187E-07"
        rpy="0 0 0" />
      <mass
        value="0.0110925597603562" />
      <inertia
        ixx="1.26410691718137E-06"
        ixy="-1.5460162528858E-07"
        ixz="1.36519585539842E-07"
        iyy="1.02513832514045E-06"
        iyz="-6.70299050271453E-08"
        izz="1.00842045851304E-06" />
    </inertial>
    <visual>
      <origin
        xyz="0 0 0"
        rpy="0 0 0" />
      <geometry>
        <mesh
          filename="file://$(find icarus_pi)/Mesh/Mecanum-Right/meshes/Right_Base_Link.STL" />
      </geometry>
      <material
        name="">
        <color
          rgba="0.792156862745098 0.819607843137255 0.933333333333333 1" />
      </material>
    </visual>
    <collision>
      <origin
        xyz="0 0 0"
        rpy="0 0 0" />
      <geometry>
        <mesh
          filename="file://$(find icarus_pi)/Mesh/Mecanum-Right/meshes/Right_Base_Link.STL" />
      </geometry>
    </collision>
  </link>
  <joint name="${prefix}_joint" type="continuous"> 
		<parent link="base_link"/>
		<child link="${prefix}_link"/>
		<origin xyz="${x_reflect*wheel_xoff} ${y_reflect*(chassis_width/2 + wheel_ygap)} ${-wheel_zoff}" rpy="0 0 0"/>
    <axis xyz="0 0 1"/>
	</joint>
  <link
    name="${prefix}_Mecanum_Roller_Link1">
    <inertial>
      <origin
        xyz="-4.16595979552251E-05 0 1.56125112837913E-17"
        rpy="0 0 0" />
      <mass
        value="0.00104310145784987" />
      <inertia
        ixx="9.96758957260102E-09"
        ixy="2.95006210648795E-24"
        ixz="2.48154183765908E-24"
        iyy="3.79225492604175E-08"
        iyz="-1.60266243682149E-24"
        izz="3.79225492604175E-08" />
    </inertial>
    <visual>
      <origin
        xyz="0 0 0"
        rpy="0 0 0" />
      <geometry>
        <mesh
          filename="file://$(find icarus_pi)/Mesh/Mecanum-Right/meshes/Mecanum_Roller_Link1.STL" />
      </geometry>
      <material
        name="">
        <color
          rgba="0.792156862745098 0.819607843137255 0.933333333333333 1" />
      </material>
    </visual>
    <collision>
      <origin
        xyz="0 0 0"
        rpy="0 0 0" />
      <geometry>
        <mesh
          filename="file://$(find icarus_pi)/Mesh/Mecanum-Right/meshes/Mecanum_Roller_Link1.STL" />
      </geometry>
    </collision>
  </link>
  <joint
    name="${prefix}_Mecanum_Roller_Joint_1"
    type="continuous">
    <origin
      xyz="-0.00786276516006295 -0.00229210366796707 0.0151828566548909"
      rpy="-1.36068806852681 0.491674447872911 -2.73783219400761" />
    <parent
      link="${prefix}_link" />
    <child
      link="${prefix}_Mecanum_Roller_Link1" />
    <axis
      xyz="1 0 0" />
  </joint>
  <link
    name="${prefix}_Mecanum_Roller_Link2">
    <inertial>
      <origin
        xyz="-4.19537259518619E-05 5.55111512312578E-17 4.5102810375397E-17"
        rpy="0 0 0" />
      <mass
        value="0.00104310145784987" />
      <inertia
        ixx="9.96758957260102E-09"
        ixy="4.13590306276514E-25"
        ixz="8.27180612553028E-25"
        iyy="3.79225492604175E-08"
        iyz="0"
        izz="3.79225492604175E-08" />
    </inertial>
    <visual>
      <origin
        xyz="0 0 0"
        rpy="0 0 0" />
      <geometry>
        <mesh
          filename="file://$(find icarus_pi)/Mesh/Mecanum-Right/meshes/Mecanum_Roller_Link2.STL" />
      </geometry>
      <material
        name="">
        <color
          rgba="0.792156862745098 0.819607843137255 0.933333333333333 1" />
      </material>
    </visual>
    <collision>
      <origin
        xyz="0 0 0"
        rpy="0 0 0" />
      <geometry>
        <mesh
          filename="file://$(find icarus_pi)/Mesh/Mecanum-Right/meshes/Mecanum_Roller_Link2.STL" />
      </geometry>
    </collision>
  </link>
  <joint
    name="${prefix}_Mecanum_Roller_Joint_2"
    type="continuous">
    <origin
      xyz="-0.00257449912034201 0.00825350947765706 0.0149280771357719"
      rpy="1.93542758330994 -0.0214038442701011 0.265392618762669" />
    <parent
      link="${prefix}_link" />
    <child
      link="${prefix}_Mecanum_Roller_Link2" />
    <axis
      xyz="1 0 0" />
  </joint>
  <link
    name="${prefix}_Mecanum_Roller_Link3">
    <inertial>
      <origin
        xyz="-4.16595979550827E-05 -1.73472347597681E-18 -1.73472347597681E-18"
        rpy="0 0 0" />
      <mass
        value="0.00104310145784987" />
      <inertia
        ixx="9.96758957260103E-09"
        ixy="1.88700577238659E-24"
        ixz="4.44609579247252E-24"
        iyy="3.79225492604175E-08"
        iyz="-4.13590306276514E-25"
        izz="3.79225492604175E-08" />
    </inertial>
    <visual>
      <origin
        xyz="0 0 0"
        rpy="0 0 0" />
      <geometry>
        <mesh
          filename="file://$(find icarus_pi)/Mesh/Mecanum-Right/meshes/Mecanum_Roller_Link3.STL" />
      </geometry>
      <material
        name="">
        <color
          rgba="0.792156862745098 0.819607843137255 0.933333333333333 1" />
      </material>
    </visual>
    <collision>
      <origin
        xyz="0 0 0"
        rpy="0 0 0" />
      <geometry>
        <mesh
          filename="file://$(find icarus_pi)/Mesh/Mecanum-Right/meshes/Mecanum_Roller_Link3.STL" />
      </geometry>
    </collision>
  </link>
  <joint
    name="${prefix}_Mecanum_Roller_Joint_3"
    type="continuous">
    <origin
      xyz="0.0038677825728569 0.0149620683207087 0.00766633686486059"
      rpy="-1.45997240902279 -0.325004631734415 3.05656776956051" />
    <parent
      link="${prefix}_link" />
    <child
      link="${prefix}_Mecanum_Roller_Link3" />
    <axis
      xyz="1 0 0" />
  </joint>
  <link
    name="${prefix}_Mecanum_Roller_Link4">
    <inertial>
      <origin
        xyz="4.16595979567443E-05 0 -1.73472347597681E-18"
        rpy="0 0 0" />
      <mass
        value="0.00104310145784984" />
      <inertia
        ixx="9.96758957238032E-09"
        ixy="-2.06795153138257E-24"
        ixz="-5.58346913473294E-24"
        iyy="3.79225492603072E-08"
        iyz="-4.96308367531817E-24"
        izz="3.79225492603072E-08" />
    </inertial>
    <visual>
      <origin
        xyz="0 0 0"
        rpy="0 0 0" />
      <geometry>
        <mesh
          filename="file://$(find icarus_pi)/Mesh/Mecanum-Right/meshes/Mecanum_Roller_Link4.STL" />
      </geometry>
      <material
        name="">
        <color
          rgba="0.792156862745098 0.819607843137255 0.933333333333333 1" />
      </material>
    </visual>
    <collision>
      <origin
        xyz="0 0 0"
        rpy="0 0 0" />
      <geometry>
        <mesh
          filename="file://$(find icarus_pi)/Mesh/Mecanum-Right/meshes/Mecanum_Roller_Link4.STL" />
      </geometry>
    </collision>
  </link>
  <joint
    name="${prefix}_Mecanum_Roller_Joint_4"
    type="continuous">
    <origin
      xyz="0.00844966471730028 0.0146945636211975 -0.00320451517983013"
      rpy="-1.23509707840396 0.401303910502291 -0.602154738197085" />
    <parent
      link="${prefix}_link" />
    <child
      link="${prefix}_Mecanum_Roller_Link4" />
    <axis
      xyz="1 0 0" />
  </joint>
  <link
    name="${prefix}_Mecanum_Roller_Link5">
    <inertial>
      <origin
        xyz="4.16595979569898E-05 3.64291929955129E-17 -1.38777878078145E-17"
        rpy="0 0 0" />
      <mass
        value="0.0010431014578499" />
      <inertia
        ixx="9.96758957260262E-09"
        ixy="2.06795153138257E-25"
        ixz="2.06795153138257E-24"
        iyy="3.79225492604183E-08"
        iyz="2.06795153138257E-24"
        izz="3.79225492604183E-08" />
    </inertial>
    <visual>
      <origin
        xyz="0 0 0"
        rpy="0 0 0" />
      <geometry>
        <mesh
          filename="file://$(find icarus_pi)/Mesh/Mecanum-Right/meshes/Mecanum_Roller_Link5.STL" />
      </geometry>
      <material
        name="">
        <color
          rgba="0.792156862745098 0.819607843137255 0.933333333333333 1" />
      </material>
    </visual>
    <collision>
      <origin
        xyz="0 0 0"
        rpy="0 0 0" />
      <geometry>
        <mesh
          filename="file://$(find icarus_pi)/Mesh/Mecanum-Right/meshes/Mecanum_Roller_Link5.STL" />
      </geometry>
    </collision>
  </link>
  <joint
    name="${prefix}_Mecanum_Roller_Joint_5"
    type="continuous">
    <origin
      xyz="0.00902723373565527 0.0075761638010083 -0.0125978865105267"
      rpy="1.01038415879456 0.159830081855345 -1.04575970415485" />
    <parent
      link="${prefix}_link" />
    <child
      link="${prefix}_Mecanum_Roller_Link5" />
    <axis
      xyz="1 0 0" />
  </joint>
  <link
    name="${prefix}_Mecanum_Roller_Link6">
    <inertial>
      <origin
        xyz="4.16595979573133E-05 -6.93889390390723E-18 1.73472347597681E-18"
        rpy="0 0 0" />
      <mass
        value="0.00104310145784987" />
      <inertia
        ixx="9.96758957260103E-09"
        ixy="1.75775880167518E-24"
        ixz="2.8951321439356E-24"
        iyy="3.79225492604175E-08"
        iyz="2.99852972050473E-24"
        izz="3.79225492604175E-08" />
    </inertial>
    <visual>
      <origin
        xyz="0 0 0"
        rpy="0 0 0" />
      <geometry>
        <mesh
          filename="file://$(find icarus_pi)/Mesh/Mecanum-Right/meshes/Mecanum_Roller_Link6.STL" />
      </geometry>
      <material
        name="">
        <color
          rgba="0.792156862745098 0.819607843137255 0.933333333333333 1" />
      </material>
    </visual>
    <collision>
      <origin
        xyz="0 0 0"
        rpy="0 0 0" />
      <geometry>
        <mesh
          filename="file://$(find icarus_pi)/Mesh/Mecanum-Right/meshes/Mecanum_Roller_Link6.STL" />
      </geometry>
    </collision>
  </link>
  <joint
    name="${prefix}_Mecanum_Roller_Joint_6"
    type="continuous">
    <origin
      xyz="0.00533023866526893 -0.00306235275179063 -0.0161185142859026"
      rpy="-1.00833638122774 -0.270056335980709 -1.28003202448786" />
    <parent
      link="${prefix}_link" />
    <child
      link="${prefix}_Mecanum_Roller_Link6" />
    <axis
      xyz="1 0 0" />
  </joint>
  <link
    name="${prefix}_Mecanum_Roller_Link7">
    <inertial>
      <origin
        xyz="4.19537259526218E-05 2.94902990916057E-17 1.38777878078145E-17"
        rpy="0 0 0" />
      <mass
        value="0.00104310145784982" />
      <inertia
        ixx="9.967589571584E-09"
        ixy="1.55096364853693E-24"
        ixz="-5.37667398159468E-24"
        iyy="3.79225492598888E-08"
        iyz="-1.24077091882954E-24"
        izz="3.79225492598888E-08" />
    </inertial>
    <visual>
      <origin
        xyz="0 0 0"
        rpy="0 0 0" />
      <geometry>
        <mesh
          filename="file://$(find icarus_pi)/Mesh/Mecanum-Right/meshes/Mecanum_Roller_Link7.STL" />
      </geometry>
      <material
        name="">
        <color
          rgba="0.792156862745098 0.819607843137255 0.933333333333333 1" />
      </material>
    </visual>
    <collision>
      <origin
        xyz="0 0 0"
        rpy="0 0 0" />
      <geometry>
        <mesh
          filename="file://$(find icarus_pi)/Mesh/Mecanum-Right/meshes/Mecanum_Roller_Link7.STL" />
      </geometry>
    </collision>
  </link>
  <joint
    name="${prefix}_Mecanum_Roller_Joint_7"
    type="continuous">
    <origin
      xyz="-0.000911455412901512 -0.0122431059082033 -0.0121190576424399"
      rpy="0.755293558147071 0.758576984655219 1.85745610617137" />
    <parent
      link="${prefix}_link" />
    <child
      link="${prefix}_Mecanum_Roller_Link7" />
    <axis
      xyz="1 0 0" />
  </joint>
  <link
    name="${prefix}_Mecanum_Roller_Link8">
    <inertial>
      <origin
        xyz="-4.19537259514699E-05 1.38777878078145E-17 -1.21430643318376E-17"
        rpy="0 0 0" />
      <mass
        value="0.00104310145784987" />
      <inertia
        ixx="9.96758957260103E-09"
        ixy="-1.55096364853693E-24"
        ixz="-2.06795153138257E-25"
        iyy="3.79225492604175E-08"
        iyz="-3.30872245021211E-24"
        izz="3.79225492604175E-08" />
    </inertial>
    <visual>
      <origin
        xyz="0 0 0"
        rpy="0 0 0" />
      <geometry>
        <mesh
          filename="file://$(find icarus_pi)/Mesh/Mecanum-Right/meshes/Mecanum_Roller_Link8.STL" />
      </geometry>
      <material
        name="">
        <color
          rgba="0.792156862745098 0.819607843137255 0.933333333333333 1" />
      </material>
    </visual>
    <collision>
      <origin
        xyz="0 0 0"
        rpy="0 0 0" />
      <geometry>
        <mesh
          filename="file://$(find icarus_pi)/Mesh/Mecanum-Right/meshes/Mecanum_Roller_Link8.STL" />
      </geometry>
    </collision>
  </link>
  <joint
    name="${prefix}_Mecanum_Roller_Joint_8"
    type="continuous">
    <origin
      xyz="-0.00677729047097743 -0.0156703192336383 -0.00247090679262434"
      rpy="2.95463100680286 -1.13639269714102 -0.725426795925048" />
    <parent
      link="${prefix}_link" />
    <child
      link="${prefix}_Mecanum_Roller_Link8" />
    <axis
      xyz="1 0 0" />
  </joint>
  <link
    name="${prefix}_Mecanum_Roller_Link9">
    <inertial>
      <origin
        xyz="-4.16595979555983E-05 -5.20417042793042E-18 6.93889390390723E-18"
        rpy="0 0 0" />
      <mass
        value="0.00104310145784987" />
      <inertia
        ixx="9.96758957260103E-09"
        ixy="1.24077091882954E-24"
        ixz="4.66581564268192E-24"
        iyy="3.79225492604175E-08"
        iyz="4.13590306276514E-25"
        izz="3.79225492604175E-08" />
    </inertial>
    <visual>
      <origin
        xyz="0 0 0"
        rpy="0 0 0" />
      <geometry>
        <mesh
          filename="file://$(find icarus_pi)/Mesh/Mecanum-Right/meshes/Mecanum_Roller_Link9.STL" />
      </geometry>
      <material
        name="">
        <color
          rgba="0.792156862745098 0.819607843137255 0.933333333333333 1" />
      </material>
    </visual>
    <collision>
      <origin
        xyz="0 0 0"
        rpy="0 0 0" />
      <geometry>
        <mesh
          filename="file://$(find icarus_pi)/Mesh/Mecanum-Right/meshes/Mecanum_Roller_Link9.STL" />
      </geometry>
    </collision>
  </link>
  <joint
    name="${prefix}_Mecanum_Roller_Joint_9"
    type="continuous">
    <origin
      xyz="-0.00952257709379006 -0.011740361523891 0.00831146125366275"
      rpy="0.326455693966909 0.964739218565908 -2.90683123969866" />
    <parent
      link="${prefix}_link" />
    <child
      link="${prefix}_Mecanum_Roller_Link9" />
    <axis
      xyz="1 0 0" />
  </joint>
  </xacro:macro>
</robot>