<?xml version="1.0"?>
<robot xmlns:xacro="http://www.ros.org/wiki/xacro" >
  <xacro:macro name="Mecanum" params="prefix x_reflect y_reflect r_reflect">
  <link
    name="${prefix}_link">
    <inertial>
      <origin
        xyz="0.011813 0.0074643 0.015042"
        rpy="0 0 0" />
      <mass
        value="0.010056" />
      <inertia
        ixx="1.2854E-06"
        ixy="-1.0402E-23"
        ixz="-1.8029E-21"
        iyy="9.0867E-07"
        iyz="-3.7562E-23"
        izz="9.0867E-07" />
    </inertial>
    <visual>
      <origin
        xyz="0 0 0"
        rpy="0 0 0" />
      <geometry>
        <mesh
          filename="file://$(find icarus_pi)/Mesh/Mecanum-Left/meshes/base_link.STL" />
      </geometry>
      <material
        name="">
        <color
          rgba="0.79216 0.81961 0.93333 1" />
      </material>
    </visual>
    <collision>
      <origin
        xyz="0 0 0"
        rpy="0 0 0" />
      <geometry>
        <mesh
          filename="file://$(find icarus_pi)/Mesh/Mecanum-Left/meshes/base_link.STL" />
      </geometry>
    </collision>
  </link>
    <joint name="${prefix}_joint" type="continuous"> 
              <parent link="base_link"/>
              <child link="${prefix}_link"/>
              <origin xyz="${x_reflect*wheel_xoff} ${y_reflect*(chassis_width/2 + wheel_ygap)} ${-wheel_zoff}" rpy="0 0 ${r_reflect}"/>
    <axis xyz="1 0 0"/>
        </joint>
  <link
    name="Mecanum_roller_link_1">
    <inertial>
      <origin
        xyz="0.012194 1.7694E-16 -2.3592E-16"
        rpy="0 0 0" />
      <mass
        value="0.0010939" />
      <inertia
        ixx="1.1179E-08"
        ixy="1.3442E-24"
        ixz="4.1359E-25"
        iyy="3.946E-08"
        iyz="-2.068E-24"
        izz="3.946E-08" />
    </inertial>
    <visual>
      <origin
        xyz="0 0 0"
        rpy="0 0 0" />
      <geometry>
        <mesh
          filename="file://$(find icarus_pi)/Mesh/Mecanum-Left/meshes/Mecanum_roller_link_1.STL" />
      </geometry>
      <material
        name="">
        <color
          rgba="0.79216 0.81961 0.93333 1" />
      </material>
    </visual>
    <collision>
      <origin
        xyz="0 0 0"
        rpy="0 0 0" />
      <geometry>
        <mesh
          filename="file://$(find icarus_pi)/Mesh/Mecanum-Left/meshes/Mecanum_roller_link_1.STL" />
      </geometry>
    </collision>
  </link>
  <joint
    name="${prefix}_Mecanum_roller_joint_1" type="continuous">
    <origin
      xyz="0.0032354879777911 -0.0211628583855368 0.0257385293646238"
      rpy="1.40087787206783 0.523598775598295 -0.615479708670392" />
    <parent
      link="${prefix}_link" />
    <child
      link="${prefix}_Mecanum_roller_link_1" />
    <axis
      xyz="1 0 0" />
  </joint>
  <link
    name="${prefix}_Mecanum_roller_link_2">
    <inertial>
      <origin
        xyz="0.0029529 -4.3368E-18 1.0408E-17"
        rpy="0 0 0" />
      <mass
        value="0.0010939" />
      <inertia
        ixx="1.1179E-08"
        ixy="-3.6706E-24"
        ixz="-3.3087E-24"
        iyy="3.946E-08"
        iyz="0"
        izz="3.946E-08" />
    </inertial>
    <visual>
      <origin
        xyz="0 0 0"
        rpy="0 0 0" />
      <geometry>
        <mesh
          filename="file://$(find icarus_pi)/Mesh/Mecanum-Left/meshes/Mecanum_roller_link_2.STL" />
      </geometry>
      <material
        name="">
        <color
          rgba="0.79216 0.81961 0.93333 1" />
      </material>
    </visual>
    <collision>
      <origin
        xyz="0 0 0"
        rpy="0 0 0" />
      <geometry>
        <mesh
          filename="file://$(find icarus_pi)/Mesh/Mecanum-Left/meshes/Mecanum_roller_link_2.STL" />
      </geometry>
    </collision>
  </link>
  <joint
    name="${prefix}_Mecanum_roller_joint_2"
    type="continuous">
    <origin
      xyz="0.013855 -0.025783 -0.0061895"
      rpy="1.3738 -0.5236 -2.5261" />
    <parent
      link="${prefix}_link" />
    <child
      link="${prefix}_Mecanum_roller_link_2" />
    <axis
      xyz="1 0 0" />
  </joint>
  <link
    name="${prefix}_Mecanum_roller_link_3">
    <inertial>
      <origin
        xyz="-0.0023361 1.3878E-17 6.9389E-18"
        rpy="0 0 0" />
      <mass
        value="0.0010939" />
      <inertia
        ixx="1.1179E-08"
        ixy="1.4362E-22"
        ixz="-4.26E-23"
        iyy="3.946E-08"
        iyz="-4.1359E-24"
        izz="3.946E-08" />
    </inertial>
    <visual>
      <origin
        xyz="0 0 0"
        rpy="0 0 0" />
      <geometry>
        <mesh
          filename="file://$(find icarus_pi)/Mesh/Mecanum-Left/meshes/Mecanum_roller_link_3.STL" />
      </geometry>
      <material
        name="">
        <color
          rgba="0.79216 0.81961 0.93333 1" />
      </material>
    </visual>
    <collision>
      <origin
        xyz="0 0 0"
        rpy="0 0 0" />
      <geometry>
        <mesh
          filename="file://$(find icarus_pi)/Mesh/Mecanum-Left/meshes/Mecanum_roller_link_3.STL" />
      </geometry>
    </collision>
  </link>
  <joint
    name="${prefix}_Mecanum_roller_joint_3"
    type="continuous">
    <origin
      xyz="0.0134188663284221 -0.0134188663284221 -0.00978574865900883"
      rpy="1.84520374289531 0 0.78539816339745" />
    <parent
      link="${prefix}_link" />
    <child
      link="${prefix}_Mecanum_roller_link_3" />
    <axis
      xyz="1 0 0" />
  </joint>
  <link
    name="${prefix}_Mecanum_roller_link_4">
    <inertial>
      <origin
        xyz="0.0030222 0 2.0817E-17"
        rpy="0 0 0" />
      <mass
        value="0.0010939" />
      <inertia
        ixx="1.1179E-08"
        ixy="-3.2743E-23"
        ixz="-1.4241E-22"
        iyy="3.946E-08"
        iyz="-8.2718E-25"
        izz="3.946E-08" />
    </inertial>
    <visual>
      <origin
        xyz="0 0 0"
        rpy="0 0 0" />
      <geometry>
        <mesh
          filename="file://$(find icarus_pi)/Mesh/Mecanum-Left/meshes/Mecanum_roller_link_4.STL" />
      </geometry>
      <material
        name="">
        <color
          rgba="0.79216 0.81961 0.93333 1" />
      </material>
    </visual>
    <collision>
      <origin
        xyz="0 0 0"
        rpy="0 0 0" />
      <geometry>
        <mesh
          filename="file://$(find icarus_pi)/Mesh/Mecanum-Left/meshes/Mecanum_roller_link_4.STL" />
      </geometry>
    </collision>
  </link>
  <joint
    name="${prefix}_Mecanum_roller_joint_4"
    type="continuous">
    <origin
      xyz="0.00963 -0.032292 0.00963"
      rpy="1.7863 0.7854 0" />
    <parent
      link="${prefix}_link" />
    <child
      link="${prefix}_Mecanum_roller_link_4" />
    <axis
      xyz="1 0 0" />
  </joint>
  <link
    name="${prefix}_Mecanum_roller_link_5">
    <inertial>
      <origin
        xyz="0.013578 2.8623E-17 -7.546E-17"
        rpy="0 0 0" />
      <mass
        value="0.0010939" />
      <inertia
        ixx="1.1179E-08"
        ixy="-3.4704E-23"
        ixz="1.4829E-22"
        iyy="3.946E-08"
        iyz="-8.2718E-25"
        izz="3.946E-08" />
    </inertial>
    <visual>
      <origin
        xyz="0 0 0"
        rpy="0 0 0" />
      <geometry>
        <mesh
          filename="file://$(find icarus_pi)/Mesh/Mecanum-Left/meshes/Mecanum_roller_link_5.STL" />
      </geometry>
      <material
        name="">
        <color
          rgba="0.79216 0.81961 0.93333 1" />
      </material>
    </visual>
    <collision>
      <origin
        xyz="0 0 0"
        rpy="0 0 0" />
      <geometry>
        <mesh
          filename="file://$(find icarus_pi)/Mesh/Mecanum-Left/meshes/Mecanum_roller_link_5.STL" />
      </geometry>
    </collision>
  </link>
  <joint
    name="${prefix}_Mecanum_roller_joint_5"
    type="continuous">
    <origin
      xyz="0.0021658 0.002208 -0.0021658"
      rpy="1.2964 -0.7854 0" />
    <parent
      link="${prefix}_link" />
    <child
      link="${prefix}_Mecanum_roller_joint_5" />
    <axis
      xyz="1 0 0" />
  </joint>
  <link
    name="${prefix}_Mecanum_roller_link_6">
    <inertial>
      <origin
        xyz="0.0045113 1.2143E-17 1.7347E-18"
        rpy="0 0 0" />
      <mass
        value="0.0010939" />
      <inertia
        ixx="1.1179E-08"
        ixy="-3.8774E-24"
        ixz="0"
        iyy="3.946E-08"
        iyz="-1.6544E-24"
        izz="3.946E-08" />
    </inertial>
    <visual>
      <origin
        xyz="0 0 0"
        rpy="0 0 0" />
      <geometry>
        <mesh
          filename="file://$(find icarus_pi)/Mesh/Mecanum-Left/meshes/Mecanum_roller_link_6.STL" />
      </geometry>
      <material
        name="">
        <color
          rgba="0.79216 0.81961 0.93333 1" />
      </material>
    </visual>
    <collision>
      <origin
        xyz="0 0 0"
        rpy="0 0 0" />
      <geometry>
        <mesh
          filename="file://$(find icarus_pi)/Mesh/Mecanum-Left/meshes/Mecanum_roller_link_6.STL" />
      </geometry>
    </collision>
  </link>
  <joint
    name="${prefix}_Mecanum_roller_joint_6"
    type="continuous">
    <origin
      xyz="0.00857701202220883 -0.00512037328736673 -0.00700935343907806"
      rpy="1.40087787206783 -0.523598775598296 0.615479708670392" />
    <parent
      link="${prefix}_link" />
    <child
      link="${prefix}_Mecanum_roller_link_6" />
    <axis
      xyz="1 0 0" />
  </joint>
  <link
    name="${prefix}_Mecanum_roller_link_7">
    <inertial>
      <origin
        xyz="0.018106 -5.2042E-18 3.4694E-18"
        rpy="0 0 0" />
      <mass
        value="0.0010939" />
      <inertia
        ixx="1.1179E-08"
        ixy="3.6189E-24"
        ixz="-4.1359E-25"
        iyy="3.946E-08"
        iyz="0"
        izz="3.946E-08" />
    </inertial>
    <visual>
      <origin
        xyz="0 0 0"
        rpy="0 0 0" />
      <geometry>
        <mesh
          filename="file://$(find icarus_pi)/Mesh/Mecanum-Left/meshes/Mecanum_roller_link_7.STL" />
      </geometry>
      <material
        name="">
        <color
          rgba="0.79216 0.81961 0.93333 1" />
      </material>
    </visual>
    <collision>
      <origin
        xyz="0 0 0"
        rpy="0 0 0" />
      <geometry>
        <mesh
          filename="file://$(find icarus_pi)/Mesh/Mecanum-Left/meshes/Mecanum_roller_link_7.STL" />
      </geometry>
    </collision>
  </link>
  <joint
    name="${prefix}_Mecanum_roller_joint_7"
    type="continuous">
    <origin
      xyz="-0.0010359 0.006229 0.010588"
      rpy="1.5572 -0.5236 -0.61548" />
    <parent
      link="${prefix}_link" />
    <child
      link="${prefix}_Mecanum_roller_link_7" />
    <axis
      xyz="1 0 0" />
  </joint>
  <link
    name="${prefix}_Mecanum_roller_link_8">
    <inertial>
      <origin
        xyz="0 0 0"
        rpy="0 0 0" />
      <mass
        value="0.001" />
      <inertia
        ixx="0"
        ixy="0"
        ixz="0"
        iyy="0"
        iyz="0"
        izz="0" />
    </inertial>
    <visual>
      <origin
        xyz="0 0 0"
        rpy="0 0 0" />
      <geometry>
        <mesh
          filename="file://$(find icarus_pi)/Mesh/Mecanum-Left/meshes/Mecanum_roller_link_8.STL" />
      </geometry>
      <material
        name="">
        <color
          rgba="1 1 1 1" />
      </material>
    </visual>
    <collision>
      <origin
        xyz="0 0 0"
        rpy="0 0 0" />
      <geometry>
        <mesh
          filename="file://$(find icarus_pi)/Mesh/Mecanum-Left/meshes/Mecanum_roller_link_8.STL" />
      </geometry>
    </collision>
  </link>
  <joint
    name="${prefix}_Mecanum_roller_joint_8"
    type="continuous">
    <origin
      xyz="-6.3119955066443E-05 -0.00318305230455557 0.0247142513409911"
      rpy="-2.1509048893029 0 -0.78539816339745" />
    <parent
      link="${prefix}_Mecanum_roller_link_8" />
    <child
      link="Mecanum_roller_link_8" />
    <axis
      xyz="1 0 0" />
  </joint>
</robot>