<?xml version="1.0"?>
<robot name="c" xmlns:xacro="http://www.ros.org/wiki/xacro">
  <xacro:macro name="Mecanum" params="prefix x_reflect y_reflect r_reflect">
  <link
    name="${prefix}_link">
    <inertial>
      <origin
        xyz="-0.000234121527171483 0.00746425134099118 0.00346357398540496"
        rpy="0 0 0" />
      <mass
        value="0.0100561436842867" />
      <inertia
        ixx="9.08669427255961E-07"
        ixy="-4.24091622646816E-23"
        ixz="1.75713565333693E-21"
        iyy="9.08669427255961E-07"
        iyz="-5.13070575050977E-24"
        izz="1.28540947587092E-06" />
    </inertial>
    <visual>
      <origin
        xyz="0 0 0"
        rpy="0 0 0" />
      <geometry>
        <mesh
          filename="file://$(find icarus_pi)/Mesh/Mecanum-Left/meshes/base_link.STL" />
      </geometry>
      <material
        name="">
        <color
          rgba="0.792156862745098 0.819607843137255 0.933333333333333 1" />
      </material>
    </visual>
    <collision>
      <origin
        xyz="0 0 0"
        rpy="0 0 0" />
      <geometry>
        <mesh
          filename="file://$(find icarus_pi)/Mesh/Mecanum-Left/meshes/base_link.STL" />
      </geometry>
    </collision>
  </link>
    <joint name="${prefix}_joint" type="continuous"> 
                <parent link="base_link"/>
                <child link="${prefix}_link"/>
                <origin xyz="${x_reflect*wheel_xoff} ${y_reflect*(chassis_width/2 + wheel_ygap)} ${-wheel_zoff}" rpy="0 0 ${r_reflect}"/>
      <axis xyz="1 0 0"/>
	        </joint>
  <link
    name="${prefix}_Mecanum_roller_link_1">
    <inertial>
      <origin
        xyz="-0.0062458 -9.3675E-17 5.3776E-17"
        rpy="0 0 0" />
      <mass
        value="0.0010939" />
      <inertia
        ixx="1.1179E-08"
        ixy="4.5495E-24"
        ixz="4.1359E-25"
        iyy="3.946E-08"
        iyz="0"
        izz="3.946E-08" />
    </inertial>
    <visual>
      <origin
        xyz="0 0 0"
        rpy="0 0 0" />
      <geometry>
        <mesh
          filename="file://$(find icarus_pi)/Mesh/Mecanum-Left/meshes/Mecanum_roller_link_1.STL" />
      </geometry>
      <material
        name="">
        <color
          rgba="0.79216 0.81961 0.93333 1" />
      </material>
    </visual>
    <collision>
      <origin
        xyz="0 0 0"
        rpy="0 0 0" />
      <geometry>
        <mesh
          filename="file://$(find icarus_pi)/Mesh/Mecanum-Left/meshes/Mecanum_roller_link_1.STL" />
      </geometry>
    </collision>
  </link>
  <joint
    name="${prefix}_Mecanum_roller_joint_1" type="continuous">
    <origin
      xyz="0.015107 0.00099836 0.016519"
      rpy="1.4009 0.5236 0.95532" />
    <parent
      link="${prefix}_link" />
    <child
      link="${prefix}_Mecanum_roller_link_1" />
    <axis
      xyz="1 0 0" />
  </joint>
  <link
    name="${prefix}_Mecanum_roller_link_2">
    <inertial>
      <origin
        xyz="0.0061167 2.2551E-17 -1.7347E-17"
        rpy="0 0 0" />
      <mass
        value="0.0010939" />
      <inertia
        ixx="1.1179E-08"
        ixy="-1.2408E-24"
        ixz="1.2408E-24"
        iyy="3.946E-08"
        iyz="0"
        izz="3.946E-08" />
    </inertial>
    <visual>
      <origin
        xyz="0 0 0"
        rpy="0 0 0" />
      <geometry>
        <mesh
          filename="file://$(find icarus_pi)/Mesh/Mecanum-Left/meshes/Mecanum_roller_link_2.STL" />
      </geometry>
      <material
        name="">
        <color
          rgba="0.79216 0.81961 0.93333 1" />
      </material>
    </visual>
    <collision>
      <origin
        xyz="0 0 0"
        rpy="0 0 0" />
      <geometry>
        <mesh
          filename="file://$(find icarus_pi)/Mesh/Mecanum-Left/meshes/Mecanum_roller_link_2.STL" />
      </geometry>
    </collision>
  </link>
  <joint
    name="${prefix}_Mecanum_roller_joint_2"
    type="continuous">
    <origin
      xyz="0.00892546832625979 0.000816090016708404 -0.00777134275651348"
      rpy="1.37379417067013 -0.523598775598296 -0.955316618124505" />
    <parent
      link="${prefix}_link" />
    <child
      link="${prefix}_Mecanum_roller_link_2" />
    <axis
      xyz="1 0 0" />
  </joint>
  <link
    name="${prefix}_Mecanum_roller_link_3">
    <inertial>
      <origin
        xyz="-0.0023361 1.7347E-18 8.2399E-17"
        rpy="0 0 0" />
      <mass
        value="0.0010939" />
      <inertia
        ixx="1.1179E-08"
        ixy="-7.7548E-24"
        ixz="-8.2718E-24"
        iyy="3.946E-08"
        iyz="-1.2408E-24"
        izz="3.946E-08" />
    </inertial>
    <visual>
      <origin
        xyz="0 0 0"
        rpy="0 0 0" />
      <geometry>
        <mesh
          filename="file://$(find icarus_pi)/Mesh/Mecanum-Left/meshes/Mecanum_roller_link_3.STL" />
      </geometry>
      <material
        name="">
        <color
          rgba="0.79216 0.81961 0.93333 1" />
      </material>
    </visual>
    <collision>
      <origin
        xyz="0 0 0"
        rpy="0 0 0" />
      <geometry>
        <mesh
          filename="file://$(find icarus_pi)/Mesh/Mecanum-Left/meshes/Mecanum_roller_link_3.STL" />
      </geometry>
    </collision>
  </link>
  <joint
    name="${prefix}_Mecanum_roller_joint_3"
    type="continuous">
    <origin
      xyz="-0.0018572 -0.0018572 -0.0097857"
      rpy="1.8452 0 2.3562" />
    <parent
      link="${prefix}_link" />
    <child
      link="${prefix}_Mecanum_roller_link_3" />
    <axis
      xyz="1 0 0" />
  </joint>
  <link
    name="${prefix}_Mecanum_roller_link_4">
    <inertial>
      <origin
        xyz="-0.0077796 4.3368E-18 3.4694E-18"
        rpy="0 0 0" />
      <mass
        value="0.0010939" />
      <inertia
        ixx="1.1179E-08"
        ixy="2.4815E-24"
        ixz="1.2408E-24"
        iyy="3.946E-08"
        iyz="-4.1359E-25"
        izz="3.946E-08" />
    </inertial>
    <visual>
      <origin
        xyz="0 0 0"
        rpy="0 0 0" />
      <geometry>
        <mesh
          filename="file://$(find icarus_pi)/Mesh/Mecanum-Left/meshes/Mecanum_roller_link_4.STL" />
      </geometry>
      <material
        name="">
        <color
          rgba="0.79216 0.81961 0.93333 1" />
      </material>
    </visual>
    <collision>
      <origin
        xyz="0 0 0"
        rpy="0 0 0" />
      <geometry>
        <mesh
          filename="file://$(find icarus_pi)/Mesh/Mecanum-Left/meshes/Mecanum_roller_link_4.STL" />
      </geometry>
    </collision>
  </link>
  <joint
    name="${prefix}_Mecanum_roller_joint_4"
    type="continuous">
    <origin
      xyz="0.017016 0.001992 0.001992"
      rpy="1.7863 0.7854 1.5708" />
    <parent
      link="${prefix}_link" />
    <child
      link="${prefix}_Mecanum_roller_link_4" />
    <axis
      xyz="1 0 0" />
  </joint>
  <link
    name="${prefix}_Mecanum_roller_link_5">
    <inertial>
      <origin
        xyz="0.0027764 3.4694E-18 -3.4694E-18"
        rpy="0 0 0" />
      <mass
        value="0.0010939" />
      <inertia
        ixx="1.1179E-08"
        ixy="8.6854E-24"
        ixz="3.1019E-25"
        iyy="3.946E-08"
        iyz="-1.2408E-24"
        izz="3.946E-08" />
    </inertial>
    <visual>
      <origin
        xyz="0 0 0"
        rpy="0 0 0" />
      <geometry>
        <mesh
          filename="file://$(find icarus_pi)/Mesh/Mecanum-Left/meshes/Mecanum_roller_link_5.STL" />
      </geometry>
      <material
        name="">
        <color
          rgba="0.79216 0.81961 0.93333 1" />
      </material>
    </visual>
    <collision>
      <origin
        xyz="0 0 0"
        rpy="0 0 0" />
      <geometry>
        <mesh
          filename="file://$(find icarus_pi)/Mesh/Mecanum-Left/meshes/Mecanum_roller_link_5.STL" />
      </geometry>
    </collision>
  </link>
  <joint
    name="${prefix}_Mecanum_roller_joint_5"
    type="continuous">
    <origin
      xyz="-0.017484 -0.0054723 0.0054723"
      rpy="1.2964 -0.7854 1.5708" />
    <parent
      link="${prefix}_link" />
    <child
      link="${prefix}_Mecanum_roller_link_5" />
    <axis
      xyz="1 0 0" />
  </joint>
  <link
    name="${prefix}_Mecanum_roller_link_6">
    <inertial>
      <origin
        xyz="0.0013476 -1.0408E-17 5.2042E-18"
        rpy="0 0 0" />
      <mass
        value="0.0010939" />
      <inertia
        ixx="1.1179E-08"
        ixy="-4.1359E-24"
        ixz="1.6544E-24"
        iyy="3.946E-08"
        iyz="-2.4815E-24"
        izz="3.946E-08" />
    </inertial>
    <visual>
      <origin
        xyz="0 0 0"
        rpy="0 0 0" />
      <geometry>
        <mesh
          filename="file://$(find icarus_pi)/Mesh/Mecanum-Left/meshes/Mecanum_roller_link_6.STL" />
      </geometry>
      <material
        name="">
        <color
          rgba="0.79216 0.81961 0.93333 1" />
      </material>
    </visual>
    <collision>
      <origin
        xyz="0 0 0"
        rpy="0 0 0" />
      <geometry>
        <mesh
          filename="file://$(find icarus_pi)/Mesh/Mecanum-Left/meshes/Mecanum_roller_link_6.STL" />
      </geometry>
    </collision>
  </link>
  <joint
    name="${prefix}_Mecanum_roller_joint_6"
    type="continuous">
    <origin
      xyz="-0.011738 -0.0044619 -0.0054275"
      rpy="1.4009 -0.5236 2.1863" />
    <parent
      link="${prefix}_link" />
    <child
      link="${prefix}_Mecanum_roller_link_6" />
    <axis
      xyz="1 0 0" />
  </joint>
  <link
    name="${prefix}_Mecanum_roller_link_7">
    <inertial>
      <origin
        xyz="0.0011134 3.4694E-18 0"
        rpy="0 0 0" />
      <mass
        value="0.0010939" />
      <inertia
        ixx="1.1179E-08"
        ixy="6.2039E-24"
        ixz="-1.2408E-24"
        iyy="3.946E-08"
        iyz="-8.2718E-25"
        izz="3.946E-08" />
    </inertial>
    <visual>
      <origin
        xyz="0 0 0"
        rpy="0 0 0" />
      <geometry>
        <mesh
          filename="file://$(find icarus_pi)/Mesh/Mecanum-Left/meshes/Mecanum_roller_link_7.STL" />
      </geometry>
      <material
        name="">
        <color
          rgba="0.79216 0.81961 0.93333 1" />
      </material>
    </visual>
    <collision>
      <origin
        xyz="0 0 0"
        rpy="0 0 0" />
      <geometry>
        <mesh
          filename="file://$(find icarus_pi)/Mesh/Mecanum-Left/meshes/Mecanum_roller_link_7.STL" />
      </geometry>
    </collision>
  </link>
  <joint
    name="${prefix}_Mecanum_roller_joint_7"
    type="continuous">
    <origin
      xyz="-0.013009 -0.0042964 0.019085"
      rpy="1.5572 -0.5236 0.95532" />
    <parent
      link="${prefix}_link" />
    <child
      link="${prefix}_Mecanum_roller_link_7" />
    <axis
      xyz="1 0 0" />
  </joint>
  <link
    name="${prefix}_Mecanum_roller_link_8">
    <inertial>
      <origin
        xyz="0 0 0"
        rpy="0 0 0" />
      <mass
        value="0" />
      <inertia
        ixx="0"
        ixy="0"
        ixz="0"
        iyy="0"
        iyz="0"
        izz="0" />
    </inertial>
    <visual>
      <origin
        xyz="0 0 0"
        rpy="0 0 0" />
      <geometry>
        <mesh
          filename="file://$(find icarus_pi)/Mesh/Mecanum-Left/meshes/Mecanum_roller_link_8.STL" />
      </geometry>
      <material
        name="">
        <color
          rgba="1 1 1 1" />
      </material>
    </visual>
    <collision>
      <origin
        xyz="0 0 0"
        rpy="0 0 0" />
      <geometry>
        <mesh
          filename="file://$(find icarus_pi)/Mesh/Mecanum-Left/meshes/Mecanum_roller_link_8.STL" />
      </geometry>
    </collision>
  </link>
  <joint
    name="${prefix}_Mecanum_roller_joint_8"
    type="continuous">
    <origin
      xyz="0.00162308612981116 -0.00162308612981119 0.0247142513409912"
      rpy="-2.1509048893029 0 0.785398163397446" />
    <parent
      link="${prefix}_link" />
    <child
      link="${prefix}_Mecanum_roller_link_8" />
    <axis
      xyz="1 0 0" />
  </joint>
</robot>