<?xml version="1.0" encoding="utf-8"?>
<!-- This URDF was automatically created by SolidWorks to URDF Exporter! Originally created by Stephen Brawner (brawner@gmail.com) 
     Commit Version: 1.6.0-4-g7f85cfe  Build Version: 1.6.7995.38578
     For more information, please see http://wiki.ros.org/sw_urdf_exporter -->
<robot
  name="Mecanum-Right">
  <link
    name="Right_Base_Link">
    <inertial>
      <origin
        xyz="0.00465786271618246 -6.93889390390723E-18 -5.85469173142172E-18"
        rpy="0 0 0" />
      <mass
        value="0.0110925597603562" />
      <inertia
        ixx="1.39920510272198E-06"
        ixy="8.93287762618103E-22"
        ixz="2.59668373970243E-21"
        iyy="9.49230299056441E-07"
        iyz="-1.33751335600186E-22"
        izz="9.49230299056441E-07" />
    </inertial>
    <visual>
      <origin
        xyz="0 0 0"
        rpy="0 0 0" />
      <geometry>
        <mesh
          filename="package://Mecanum-Right/meshes/Right_Base_Link.STL" />
      </geometry>
      <material
        name="">
        <color
          rgba="0.792156862745098 0.819607843137255 0.933333333333333 1" />
      </material>
    </visual>
    <collision>
      <origin
        xyz="0 0 0"
        rpy="0 0 0" />
      <geometry>
        <mesh
          filename="package://Mecanum-Right/meshes/Right_Base_Link.STL" />
      </geometry>
    </collision>
  </link>
  <link
    name="Mecanum_Roller_Link1">
    <inertial>
      <origin
        xyz="0.0046501299257092 -0.0162640055968391 -0.0057506377756141"
        rpy="0 0 0" />
      <mass
        value="0.00104310145784987" />
      <inertia
        ixx="2.39450694165093E-08"
        ixy="4.78057965954515E-09"
        ixz="-1.31345346665044E-08"
        iyy="3.62874947200801E-08"
        iyz="4.49227542915381E-09"
        izz="2.55801239568466E-08" />
    </inertial>
    <visual>
      <origin
        xyz="0 0 0"
        rpy="0 0 0" />
      <geometry>
        <mesh
          filename="package://Mecanum-Right/meshes/Mecanum_Roller_Link1.STL" />
      </geometry>
      <material
        name="">
        <color
          rgba="0.792156862745098 0.819607843137255 0.933333333333333 1" />
      </material>
    </visual>
    <collision>
      <origin
        xyz="0 0 0"
        rpy="0 0 0" />
      <geometry>
        <mesh
          filename="package://Mecanum-Right/meshes/Mecanum_Roller_Link1.STL" />
      </geometry>
    </collision>
  </link>
  <joint
    name="Mecanum_Roller_1"
    type="continuous">
    <origin
      xyz="0 0 0"
      rpy="0 0 0" />
    <parent
      link="Right_Base_Link" />
    <child
      link="Mecanum_Roller_Link1" />
    <axis
      xyz="-1 0 0" />
  </joint>
  <link
    name="Mecanum_Roller_Link2">
    <inertial>
      <origin
        xyz="0.00465012992570909 -0.00876251240035445 -0.01485954539392"
        rpy="0 0 0" />
      <mass
        value="0.00104310145784987" />
      <inertia
        ixx="2.39450694165094E-08"
        ixy="1.21048526257095E-08"
        ixz="-6.98873992195412E-09"
        iyy="2.74394393774863E-08"
        iyz="6.05242631285478E-09"
        izz="3.44281792994405E-08" />
    </inertial>
    <visual>
      <origin
        xyz="0 0 0"
        rpy="0 0 0" />
      <geometry>
        <mesh
          filename="package://Mecanum-Right/meshes/Mecanum_Roller_Link2.STL" />
      </geometry>
      <material
        name="">
        <color
          rgba="0.792156862745098 0.819607843137255 0.933333333333333 1" />
      </material>
    </visual>
    <collision>
      <origin
        xyz="0 0 0"
        rpy="0 0 0" />
      <geometry>
        <mesh
          filename="package://Mecanum-Right/meshes/Mecanum_Roller_Link2.STL" />
      </geometry>
    </collision>
  </link>
  <joint
    name="Mecanum_Roller_2"
    type="continuous">
    <origin
      xyz="0 0 0"
      rpy="0 0 0" />
    <parent
      link="Right_Base_Link" />
    <child
      link="Mecanum_Roller_Link2" />
    <axis
      xyz="-1 0 0" />
  </joint>
  <link
    name="Mecanum_Roller_Link3">
    <inertial>
      <origin
        xyz="0.00465012992570885 0.00283905773273392 -0.0170155065769591"
        rpy="0 0 0" />
      <mass
        value="0.00104310145784987" />
      <inertia
        ixx="2.39450694160864E-08"
        ixy="1.37651305179916E-08"
        ixz="2.42716390329539E-09"
        iyy="2.43665420047924E-08"
        iyz="-2.39028982979668E-09"
        izz="3.75010766714294E-08" />
    </inertial>
    <visual>
      <origin
        xyz="0 0 0"
        rpy="0 0 0" />
      <geometry>
        <mesh
          filename="package://Mecanum-Right/meshes/Mecanum_Roller_Link3.STL" />
      </geometry>
      <material
        name="">
        <color
          rgba="0.792156862745098 0.819607843137255 0.933333333333333 1" />
      </material>
    </visual>
    <collision>
      <origin
        xyz="0 0 0"
        rpy="0 0 0" />
      <geometry>
        <mesh
          filename="package://Mecanum-Right/meshes/Mecanum_Roller_Link3.STL" />
      </geometry>
    </collision>
  </link>
  <joint
    name="Mecanum_Roller_3"
    type="continuous">
    <origin
      xyz="0 0 0"
      rpy="0 0 0" />
    <parent
      link="Right_Base_Link" />
    <child
      link="Mecanum_Roller_Link3" />
    <axis
      xyz="-1 0 0" />
  </joint>
  <link
    name="Mecanum_Roller_Link4">
    <inertial>
      <origin
        xyz="0.00465012992570855 0.013112201200064 -0.0112097231263478"
        rpy="0 0 0" />
      <mass
        value="0.00104310145784984" />
      <inertia
        ixx="2.39450694163438E-08"
        ixy="8.98455085834306E-09"
        ixz="1.07073707632757E-08"
        iyy="3.21473912899657E-08"
        iyz="-6.88256525895356E-09"
        izz="2.97202273866852E-08" />
    </inertial>
    <visual>
      <origin
        xyz="0 0 0"
        rpy="0 0 0" />
      <geometry>
        <mesh
          filename="package://Mecanum-Right/meshes/Mecanum_Roller_Link4.STL" />
      </geometry>
      <material
        name="">
        <color
          rgba="0.792156862745098 0.819607843137255 0.933333333333333 1" />
      </material>
    </visual>
    <collision>
      <origin
        xyz="0 0 0"
        rpy="0 0 0" />
      <geometry>
        <mesh
          filename="package://Mecanum-Right/meshes/Mecanum_Roller_Link4.STL" />
      </geometry>
    </collision>
  </link>
  <joint
    name="Mecanum_Roller_4"
    type="continuous">
    <origin
      xyz="0 0 0"
      rpy="0 0 0" />
    <parent
      link="Right_Base_Link" />
    <child
      link="Mecanum_Roller_Link4" />
    <axis
      xyz="-1 0 0" />
  </joint>
  <link
    name="Mecanum_Roller_Link5">
    <inertial>
      <origin
        xyz="0.00465012992570831 0.01725 -0.000158785642722778"
        rpy="0 0 0" />
      <mass
        value="0.00104310145784987" />
      <inertia
        ixx="2.3945069415987E-08"
        ixy="1.66526240789793E-24"
        ixz="1.39774798440688E-08"
        iyy="3.79225492600558E-08"
        iyz="-1.81331197345348E-24"
        izz="2.39450694159869E-08" />
    </inertial>
    <visual>
      <origin
        xyz="0 0 0"
        rpy="0 0 0" />
      <geometry>
        <mesh
          filename="package://Mecanum-Right/meshes/Mecanum_Roller_Link5.STL" />
      </geometry>
      <material
        name="">
        <color
          rgba="0.792156862745098 0.819607843137255 0.933333333333333 1" />
      </material>
    </visual>
    <collision>
      <origin
        xyz="0 0 0"
        rpy="0 0 0" />
      <geometry>
        <mesh
          filename="package://Mecanum-Right/meshes/Mecanum_Roller_Link5.STL" />
      </geometry>
    </collision>
  </link>
  <joint
    name="Mecanum_Roller_5"
    type="continuous">
    <origin
      xyz="0 0 0"
      rpy="0 0 0" />
    <parent
      link="Right_Base_Link" />
    <child
      link="Mecanum_Roller_Link5" />
    <axis
      xyz="-1 0 0" />
  </joint>
  <link
    name="Mecanum_Roller_Link6">
    <inertial>
      <origin
        xyz="0.0046501299257083 0.0133163320875407 0.0109664494078379"
        rpy="0 0 0" />
      <mass
        value="0.00104310145784992" />
      <inertia
        ixx="2.39450694163474E-08"
        ixy="-8.98455085835093E-09"
        ixz="1.07073707632851E-08"
        iyy="3.21473912899766E-08"
        iyz="6.88256525895961E-09"
        izz="2.97202273866939E-08" />
    </inertial>
    <visual>
      <origin
        xyz="0 0 0"
        rpy="0 0 0" />
      <geometry>
        <mesh
          filename="package://Mecanum-Right/meshes/Mecanum_Roller_Link6.STL" />
      </geometry>
      <material
        name="">
        <color
          rgba="0.792156862745098 0.819607843137255 0.933333333333333 1" />
      </material>
    </visual>
    <collision>
      <origin
        xyz="0 0 0"
        rpy="0 0 0" />
      <geometry>
        <mesh
          filename="package://Mecanum-Right/meshes/Mecanum_Roller_Link6.STL" />
      </geometry>
    </collision>
  </link>
  <joint
    name="Mecanum_Roller_6"
    type="continuous">
    <origin
      xyz="0 0 0"
      rpy="0 0 0" />
    <parent
      link="Right_Base_Link" />
    <child
      link="Mecanum_Roller_Link6" />
    <axis
      xyz="-1 0 0" />
  </joint>
  <link
    name="Mecanum_Roller_Link7">
    <inertial>
      <origin
        xyz="0.00465012992570951 0.00315180439677604 0.0169603609019619"
        rpy="0 0 0" />
      <mass
        value="0.00104310145784987" />
      <inertia
        ixx="2.39450694162558E-08"
        ixy="-1.37651305179359E-08"
        ixz="2.4271639032856E-09"
        iyy="2.43665420049602E-08"
        iyz="2.39028982978704E-09"
        izz="3.7501076671544E-08" />
    </inertial>
    <visual>
      <origin
        xyz="0 0 0"
        rpy="0 0 0" />
      <geometry>
        <mesh
          filename="package://Mecanum-Right/meshes/Mecanum_Roller_Link7.STL" />
      </geometry>
      <material
        name="">
        <color
          rgba="0.792156862745098 0.819607843137255 0.933333333333333 1" />
      </material>
    </visual>
    <collision>
      <origin
        xyz="0 0 0"
        rpy="0 0 0" />
      <geometry>
        <mesh
          filename="package://Mecanum-Right/meshes/Mecanum_Roller_Link7.STL" />
      </geometry>
    </collision>
  </link>
  <joint
    name="Mecanum_Roller_7"
    type="continuous">
    <origin
      xyz="0 0 0"
      rpy="0 0 0" />
    <parent
      link="Right_Base_Link" />
    <child
      link="Mecanum_Roller_Link7" />
    <axis
      xyz="-1 0 0" />
  </joint>
  <link
    name="Mecanum_Roller_Link8">
    <inertial>
      <origin
        xyz="0.00465012992570878 -0.00848748759964562 0.0150183310366431"
        rpy="0 0 0" />
      <mass
        value="0.00104310145784982" />
      <inertia
        ixx="2.39450694160052E-08"
        ixy="-1.2104852625855E-08"
        ixz="-6.98873992203814E-09"
        iyy="2.74394393770242E-08"
        iyz="-6.05242631292753E-09"
        izz="3.44281792990624E-08" />
    </inertial>
    <visual>
      <origin
        xyz="0 0 0"
        rpy="0 0 0" />
      <geometry>
        <mesh
          filename="package://Mecanum-Right/meshes/Mecanum_Roller_Link8.STL" />
      </geometry>
      <material
        name="">
        <color
          rgba="0.792156862745098 0.819607843137255 0.933333333333333 1" />
      </material>
    </visual>
    <collision>
      <origin
        xyz="0 0 0"
        rpy="0 0 0" />
      <geometry>
        <mesh
          filename="package://Mecanum-Right/meshes/Mecanum_Roller_Link8.STL" />
      </geometry>
    </collision>
  </link>
  <joint
    name="Mecanum_Roller_8"
    type="continuous">
    <origin
      xyz="0 0 0"
      rpy="0 0 0" />
    <parent
      link="Right_Base_Link" />
    <child
      link="Mecanum_Roller_Link8" />
    <axis
      xyz="-1 0 0" />
  </joint>
  <link
    name="Mecanum_Roller_Link9">
    <inertial>
      <origin
        xyz="0.00465012992571009 -0.0161553898202744 0.00604905716912235"
        rpy="0 0 0" />
      <mass
        value="0.00104310145784984" />
      <inertia
        ixx="2.39450694163438E-08"
        ixy="-4.78057965956403E-09"
        ixz="-1.31345346665562E-08"
        iyy="3.62874947199633E-08"
        iyz="-4.49227542917155E-09"
        izz="2.55801239566876E-08" />
    </inertial>
    <visual>
      <origin
        xyz="0 0 0"
        rpy="0 0 0" />
      <geometry>
        <mesh
          filename="package://Mecanum-Right/meshes/Mecanum_Roller_Link9.STL" />
      </geometry>
      <material
        name="">
        <color
          rgba="0.792156862745098 0.819607843137255 0.933333333333333 1" />
      </material>
    </visual>
    <collision>
      <origin
        xyz="0 0 0"
        rpy="0 0 0" />
      <geometry>
        <mesh
          filename="package://Mecanum-Right/meshes/Mecanum_Roller_Link9.STL" />
      </geometry>
    </collision>
  </link>
  <joint
    name="Mecanum_Roller_9"
    type="continuous">
    <origin
      xyz="0 0 0"
      rpy="0 0 0" />
    <parent
      link="Right_Base_Link" />
    <child
      link="Mecanum_Roller_Link9" />
    <axis
      xyz="-1 0 0" />
  </joint>
</robot>